File: varmintal/material_properties.csv
Material Name,Density (tonne/mmÂ³),Young's Modulus (MPa),Shear Modulus (MPa),Bulk Modulus (MPa),Poisson's Ratio,Yield Stress (MPa),Ultimate Stress (MPa),Elongation (%),CTE (1/C),Yield Offset (%)
ALUMINUM PURE 99.996 ANNEALED,2.6850E-09,6.8948E+04,2.5920E+04,6.7596E+04,0.3300,1.2411E+01,4.8263E+01,50.000,2.3760E-11,0.2000
ALUMINUM PURE 99.45-O CONDITION,2.7126E-09,6.8948E+04,2.5920E+04,6.7596E+04,0.3300,2.7579E+01,8.2737E+01,30.000,2.3760E-11,0.2000
ALUMINUM PURE-H12 SHEET,2.7126E-09,6.8948E+04,2.5920E+04,6.7596E+04,0.3300,8.2737E+01,9.6527E+01,8.000,2.3760E-11,0.2000
ALUMINUM PURE-H16 SHEET,2.7126E-09,6.8948E+04,2.5920E+04,6.7596E+04,0.3300,1.1032E+02,1.2411E+02,4.000,2.3760E-11,0.2000
ALUMINUM 1060-O SHEET,2.7126E-09,6.8948E+04,2.5920E+04,6.7596E+04,0.3300,2.7579E+01,6.8948E+01,43.000,2.3580E-11,0.2000
ALUMINUM 1060-H12 SHEET,2.7126E-09,6.8948E+04,2.5920E+04,6.7596E+04,0.3300,7.5842E+01,8.2737E+01,16.000,2.3580E-11,0.2000
ALUMINUM 1060-H18 SHEET,2.7126E-09,6.8948E+04,2.5920E+04,6.7596E+04,0.3300,1.2411E+02,1.3100E+02,6.000,2.3580E-11,0.2000
ALUMINUM 1100-O SHEET,2.7126E-09,6.8948E+04,2.5920E+04,6.7596E+04,0.3300,3.4474E+01,9.6527E+01,35.000,2.3580E-11,0.2000
ALUMINUM 1100-H14 SHEET,2.7126E-09,6.8948E+04,2.5920E+04,6.7596E+04,0.3300,1.1721E+02,1.2411E+02,13.000,2.3580E-11,0.2000
ALUMINUM 1100-H18 SHEET,2.7126E-09,6.8948E+04,2.5920E+04,6.7596E+04,0.3300,1.7926E+02,1.9305E+02,6.000,2.3580E-11,0.2000
ALUMINUM 2011-T3 BAR,2.8233E-09,7.0327E+04,2.6439E+04,6.8948E+04,0.3300,2.9647E+02,3.7921E+02,15.000,2.2860E-11,0.2000
ALUMINUM 2011-T8 BAR,2.8233E-09,7.0327E+04,2.6439E+04,6.8948E+04,0.3300,3.1026E+02,4.0679E+02,12.000,2.2860E-11,0.2000
ALUMINUM 2014-O BAR,2.7957E-09,7.3084E+04,2.7475E+04,7.1651E+04,0.3300,9.6527E+01,1.8616E+02,18.000,2.3040E-11,0.2000
ALUMINUM 2014-T6 SHEET,2.7957E-09,7.3084E+04,2.7475E+04,7.1651E+04,0.3300,4.6884E+02,5.1021E+02,10.000,2.3040E-11,0.2000
ALUMINUM 2014-T651,2.7957E-09,7.3084E+04,2.7475E+04,7.1651E+04,0.3300,4.3782E+02,4.7574E+02,10.200,2.3040E-11,0.2000
ALUMINUM 2017-O BAR,2.7957E-09,7.2395E+04,2.7216E+04,7.0975E+04,0.3300,6.8948E+01,1.7926E+02,22.000,2.3580E-11,0.2000
ALUMINUM 2017-T4 BAR,2.7957E-09,7.2395E+04,2.7216E+04,7.0975E+04,0.3300,2.7579E+02,4.2748E+02,22.000,2.3580E-11,0.2000
ALUMINUM 2021-O SHEET,2.8510E-09,7.3774E+04,2.7735E+04,7.2327E+04,0.3300,6.8948E+01,1.6547E+02,23.000,2.2680E-11,0.2000
ALUMINUM 2021-T31 SHEET,2.8510E-09,7.3774E+04,2.7735E+04,7.2327E+04,0.3300,2.7579E+02,4.1369E+02,20.000,2.2680E-11,0.2000
ALUMINUM 2021-T81 PLATE,2.8510E-09,7.3774E+04,2.7735E+04,7.2327E+04,0.3300,4.3437E+02,5.0332E+02,9.000,2.2680E-11,0.2000
ALUMINUM 2021-T8151,2.8510E-09,7.3774E+04,2.7735E+04,7.2327E+04,0.3300,4.5919E+02,5.1297E+02,8.000,2.2680E-11,0.2000
ALUMINUM 2024-O SHEET,2.7680E-09,7.3084E+04,2.7475E+04,7.1651E+04,0.3300,7.5842E+01,1.8616E+02,12.000,2.3220E-11,0.2000
ALUMINUM 2024-T3 SHEET,2.7680E-09,7.3084E+04,2.7475E+04,7.1651E+04,0.3300,3.5163E+02,4.6884E+02,18.000,2.3220E-11,0.2000
ALUMINUM 2024-T4 SHEET,2.7680E-09,7.3084E+04,2.7475E+04,7.1651E+04,0.3300,3.2405E+02,4.6884E+02,15.000,2.3220E-11,0.2000
ALUMINUM 2024-T851 PLATE,2.7680E-09,7.3084E+04,2.7475E+04,7.1651E+04,0.3300,4.6884E+02,4.9642E+02,8.000,2.3220E-11,0.2000
ALUMINUM 2025-T6 PLATE,2.7957E-09,7.1705E+04,2.6957E+04,7.0300E+04,0.3300,2.5511E+02,3.9990E+02,19.000,2.2680E-11,0.2000
ALUMINUM 2219-O SHEET,2.8233E-09,7.3084E+04,2.7475E+04,7.1651E+04,0.3300,7.5842E+01,1.7237E+02,18.000,2.2320E-11,0.2000
ALUMINUM 2219-T31 SHEET,2.8233E-09,7.3084E+04,2.7475E+04,7.1651E+04,0.3300,3.1026E+02,3.8611E+02,17.000,2.2320E-11,0.2000
ALUMINUM 2219-T62 SHEET,2.8233E-09,7.3084E+04,2.7475E+04,7.1651E+04,0.3300,2.6890E+02,4.0679E+02,9.000,2.2320E-11,0.2000
ALUMINUM 2219-T851 SHEET,2.8233E-09,7.3084E+04,2.7475E+04,7.1651E+04,0.3300,3.5163E+02,4.5505E+02,10.000,2.2320E-11,0.2000
ALUMINUM 2219-T851,2.8233E-09,7.3084E+04,2.7475E+04,7.1651E+04,0.3300,3.7094E+02,4.6609E+02,11.000,2.2320E-11,0.2000
ALUMINUM 2618-T6 SHEET,2.7680E-09,7.2395E+04,2.7216E+04,7.0975E+04,0.3300,3.8611E+02,4.2058E+02,6.000,2.2140E-11,0.2000
ALUMINUM 3003-O SHEET,2.7403E-09,6.8948E+04,2.5920E+04,6.7596E+04,0.3300,4.1369E+01,1.1032E+02,30.000,2.3220E-11,0.2000
ALUMINUM 3003-H12 SHEET,2.7403E-09,6.8948E+04,2.5920E+04,6.7596E+04,0.3300,1.2411E+02,1.3100E+02,10.000,2.3220E-11,0.2000
ALUMINUM 3003-H14,2.7403E-09,6.8948E+04,2.5920E+04,6.7596E+04,0.3300,1.4548E+02,1.5789E+02,16.800,2.3220E-11,0.2000
ALUMINUM 3003-H18 SHEET,2.7403E-09,6.8948E+04,2.5920E+04,6.7596E+04,0.3300,1.8616E+02,1.9995E+02,4.000,2.3220E-11,0.2000
ALUMINUM 3004-O SHEET,2.7126E-09,6.8948E+04,2.5920E+04,6.7596E+04,0.3300,6.8948E+01,1.7926E+02,20.000,2.3940E-11,0.2000
ALUMINUM 3004-H32 SHEET,2.7126E-09,6.8948E+04,2.5920E+04,6.7596E+04,0.3300,1.7237E+02,2.1374E+02,10.000,2.3940E-11,0.2000
ALUMINUM 3004-H34 SHEET,2.7126E-09,6.8948E+04,2.5920E+04,6.7596E+04,0.3300,1.9995E+02,2.4132E+02,9.000,2.3940E-11,0.2000
ALUMINUM 3004-H38 SHEET,2.7126E-09,6.8948E+04,2.5920E+04,6.7596E+04,0.3300,2.4821E+02,2.8269E+02,5.000,2.3940E-11,0.2000
ALUMINUM 4032-T6,2.6850E-09,7.8600E+04,2.9549E+04,7.7059E+04,0.3300,3.1716E+02,3.7921E+02,9.000,1.9440E-11,0.2000
ALUMINUM 5050-O SHEET,2.6850E-09,6.8948E+04,2.5920E+04,6.7596E+04,0.3300,5.5158E+01,1.4479E+02,24.000,2.3760E-11,0.2000
ALUMINUM 5050-H32 SHEET,2.6850E-09,6.8948E+04,2.5920E+04,6.7596E+04,0.3300,1.4479E+02,1.7237E+02,9.000,2.3760E-11,0.2000
ALUMINUM 5050-H34 SHEET,2.6850E-09,6.8948E+04,2.5920E+04,6.7596E+04,0.3300,1.6547E+02,1.9305E+02,8.000,2.3760E-11,0.2000
ALUMINUM 5050-H38 SHEET,2.6850E-09,6.8948E+04,2.5920E+04,6.7596E+04,0.3300,1.9995E+02,2.2063E+02,6.000,2.3760E-11,0.2000
ALUMINUM 5052-O SHEET,2.6850E-09,7.0327E+04,2.6439E+04,6.8948E+04,0.3300,8.9632E+01,1.9305E+02,25.000,2.3760E-11,0.2000
ALUMINUM 5052-O,2.6850E-09,7.0327E+04,2.6439E+04,6.8948E+04,0.3300,8.2737E+01,1.9305E+02,30.000,2.3760E-11,0.2000
ALUMINUM 5052-H34 SHEET,2.6850E-09,7.0327E+04,2.6439E+04,6.8948E+04,0.3300,2.1374E+02,2.6200E+02,10.000,2.3760E-11,0.2000
ALUMINUM 5052-H38 SHEET,2.6850E-09,7.0327E+04,2.6439E+04,6.8948E+04,0.3300,2.6200E+02,3.0337E+02,9.000,2.3760E-11,0.2000
ALUMINUM 5083-O SHEET,2.6573E-09,7.1016E+04,2.6698E+04,6.9624E+04,0.3300,1.5168E+02,3.0337E+02,23.000,2.3760E-11,0.2000
ALUMINUM 5083-O,2.6573E-09,7.1016E+04,2.6698E+04,6.9624E+04,0.3300,1.4065E+02,3.2267E+02,19.500,2.3760E-11,0.2000
ALUMINUM 5083-H12 SHEET,2.6573E-09,7.1016E+04,2.6698E+04,6.9624E+04,0.3300,3.0337E+02,3.5853E+02,10.000,2.3760E-11,0.2000
ALUMINUM 5083-H32 SHEET,2.6573E-09,7.1016E+04,2.6698E+04,6.9624E+04,0.3300,2.6200E+02,3.5163E+02,12.000,2.3760E-11,0.2000
ALUMINUM 5083-H34 SHEET,2.6573E-09,7.1016E+04,2.6698E+04,6.9624E+04,0.3300,3.1026E+02,3.7232E+02,11.000,2.3760E-11,0.2000
ALUMINUM 5083-H321,2.6573E-09,7.1016E+04,2.6698E+04,6.9624E+04,0.3300,2.3511E+02,3.3509E+02,15.000,2.3760E-11,0.2000
ALUMINUM 5086-O SHEET,2.6573E-09,7.1016E+04,2.6698E+04,6.9624E+04,0.3300,1.3100E+02,2.8269E+02,24.000,2.3760E-11,0.2000
ALUMINUM 5086-O,2.6573E-09,7.1016E+04,2.6698E+04,6.9624E+04,0.3300,1.1721E+02,2.6200E+02,30.000,2.3760E-11,0.2000
ALUMINUM 5086-H32 PLATE,2.6573E-09,7.1016E+04,2.6698E+04,6.9624E+04,0.3300,2.0684E+02,3.1026E+02,16.000,2.3760E-11,0.2000
ALUMINUM 5086-H34 SHEET,2.6573E-09,7.1016E+04,2.6698E+04,6.9624E+04,0.3300,2.6200E+02,3.4474E+02,13.000,2.3760E-11,0.2000
ALUMINUM 5086-H34 PLATE,2.6573E-09,7.1016E+04,2.6698E+04,6.9624E+04,0.3300,2.6200E+02,3.5163E+02,12.000,2.3760E-11,0.2000
ALUMINUM 5154-O SHEET,2.6573E-09,7.0327E+04,2.6439E+04,6.8948E+04,0.3300,1.1032E+02,2.4132E+02,26.000,2.3940E-11,0.2000
ALUMINUM 5154-H32 SHEET,2.6573E-09,7.0327E+04,2.6439E+04,6.8948E+04,0.3300,2.1374E+02,2.8269E+02,14.000,2.3940E-11,0.2000
ALUMINUM 5154-H34 SHEET,2.6573E-09,7.0327E+04,2.6439E+04,6.8948E+04,0.3300,2.6200E+02,3.1716E+02,10.000,2.3940E-11,0.2000
ALUMINUM 5154-H38 SHEET,2.6573E-09,7.0327E+04,2.6439E+04,6.8948E+04,0.3300,2.9647E+02,3.3784E+02,10.000,2.3940E-11,0.2000
ALUMINUM 5454-O SHEET,2.6850E-09,7.0327E+04,2.6439E+04,6.8948E+04,0.3300,1.1032E+02,2.6200E+02,22.000,2.3580E-11,0.2000
ALUMINUM 5454-O,2.6850E-09,7.0327E+04,2.6439E+04,6.8948E+04,0.3300,1.1514E+02,2.4683E+02,24.500,2.3580E-11,0.2000
ALUMINUM 5454-H32 SHEET,2.6850E-09,7.0327E+04,2.6439E+04,6.8948E+04,0.3300,2.2063E+02,2.7579E+02,11.000,2.3580E-11,0.2000
ALUMINUM 5454-H32,2.6850E-09,7.0327E+04,2.6439E+04,6.8948E+04,0.3300,1.9926E+02,2.8200E+02,15.700,2.3580E-11,0.2000
ALUMINUM 5454-H34 SHEET,2.6850E-09,7.0327E+04,2.6439E+04,6.8948E+04,0.3300,2.7579E+02,3.1716E+02,11.000,2.3580E-11,0.2000
ALUMINUM 5454-H32 PLATE,2.6850E-09,7.0327E+04,2.6439E+04,6.8948E+04,0.3300,2.6200E+02,2.7579E+02,16.000,2.3580E-11,0.2000
ALUMINUM 5456-O SHEET,2.6573E-09,7.1016E+04,2.6698E+04,6.9624E+04,0.3300,1.7237E+02,3.3784E+02,22.000,2.3940E-11,0.2000
ALUMINUM 5456-O,2.6573E-09,7.1016E+04,2.6698E+04,6.9624E+04,0.3300,1.5996E+02,3.3784E+02,21.800,2.3940E-11,0.2000
ALUMINUM 5456-H24 SHEET,2.6573E-09,7.1016E+04,2.6698E+04,6.9624E+04,0.3300,2.8269E+02,3.7232E+02,13.000,2.3940E-11,0.2000
ALUMINUM 5456-H321 SHEET,2.6573E-09,7.1016E+04,2.6698E+04,6.9624E+04,0.3300,2.5511E+02,3.5163E+02,16.000,2.3940E-11,0.2000
ALUMINUM 5456-H321 PLATE,2.6573E-09,7.1016E+04,2.6698E+04,6.9624E+04,0.3300,2.3442E+02,3.8611E+02,14.000,2.3940E-11,0.2000
ALUMINUM 6061-O SHEET,2.7126E-09,6.8948E+04,2.5920E+04,6.7596E+04,0.3300,5.5158E+01,1.2411E+02,25.000,2.3580E-11,0.2000
ALUMINUM 6061-T6 SHEET THICK,2.7126E-09,6.8948E+04,2.5920E+04,6.7596E+04,0.3300,2.8269E+02,3.1026E+02,14.000,2.3580E-11,0.2000
ALUMINUM 6061-T6 SHEET THIN,2.7126E-09,6.8948E+04,2.5920E+04,6.7596E+04,0.3300,2.9647E+02,3.2405E+02,12.000,2.3580E-11,0.2000
ALUMINUM 6061-T6,2.7126E-09,6.8948E+04,2.5920E+04,6.7596E+04,0.3300,2.9096E+02,3.0957E+02,16.500,2.3580E-11,0.2000
ALUMINUM 6061-T651 PLATE,2.7126E-09,6.8948E+04,2.5920E+04,6.7596E+04,0.3300,2.6890E+02,2.8958E+02,16.000,2.3580E-11,0.2000
ALUMINUM 6063-O SHEET,2.7126E-09,6.8948E+04,2.5920E+04,6.7596E+04,0.3300,4.8263E+01,8.9632E+01,25.000,2.3400E-11,0.2000
ALUMINUM 6063-T4 SHEET,2.7126E-09,6.8948E+04,2.5920E+04,6.7596E+04,0.3300,8.9632E+01,1.7237E+02,22.000,2.3400E-11,0.2000
ALUMINUM 6063-T6 SHEET,2.7126E-09,6.8948E+04,2.5920E+04,6.7596E+04,0.3300,2.1374E+02,2.4132E+02,12.000,2.3400E-11,0.2000
ALUMINUM 6063-T6,2.7126E-09,6.8948E+04,2.5920E+04,6.7596E+04,0.3300,2.1374E+02,2.4132E+02,18.000,2.3400E-11,0.2000
ALUMINUM 6063-T832 SHEET,2.7126E-09,6.8948E+04,2.5920E+04,6.7596E+04,0.3300,2.6890E+02,2.8958E+02,12.000,2.3400E-11,0.2000
ALUMINUM 6066-O SHEET,2.7126E-09,6.8948E+04,2.5920E+04,6.7596E+04,0.3300,8.2737E+01,1.5168E+02,20.000,2.3220E-11,0.2000
ALUMINUM 6066-T4 SHEET,2.7126E-09,6.8948E+04,2.5920E+04,6.7596E+04,0.3300,2.0684E+02,3.5853E+02,15.000,2.3220E-11,0.2000
ALUMINUM 6066-T6 SHEET,2.7126E-09,6.8948E+04,2.5920E+04,6.7596E+04,0.3300,3.5163E+02,4.0679E+02,12.000,2.3220E-11,0.2000
ALUMINUM X7005-O SHEET,2.7957E-09,7.1016E+04,2.6698E+04,6.9624E+04,0.3300,8.2737E+01,1.9305E+02,20.000,2.3760E-11,0.2000
ALUMINUM X7005-T6 SHEET,2.7957E-09,7.1016E+04,2.6698E+04,6.9624E+04,0.3300,3.1716E+02,3.5853E+02,14.000,2.3760E-11,0.2000
ALUMINUM 7005-T5351,2.7957E-09,7.1016E+04,2.6698E+04,6.9624E+04,0.3300,3.7921E+02,4.2748E+02,15.000,2.3760E-11,0.2000
ALUMINUM 7039-O SHEET,2.7957E-09,6.9637E+04,2.6179E+04,6.8272E+04,0.3300,1.0342E+02,2.2753E+02,22.000,2.3400E-11,0.2000
ALUMINUM 7039-T6 SHEET,2.7957E-09,6.9637E+04,2.6179E+04,6.8272E+04,0.3300,3.7921E+02,4.3437E+02,12.000,2.3400E-11,0.2000
ALUMINUM 7039-T61 PLATE,2.7957E-09,6.9637E+04,2.6179E+04,6.8272E+04,0.3300,3.3095E+02,3.9990E+02,14.000,2.3400E-11,0.2000
ALUMINUM 7049-T73 DIE FORGINGS,2.8233E-09,7.0327E+04,2.6439E+04,6.8948E+04,0.3300,4.2058E+02,4.8953E+02,7.000,2.3400E-11,0.2000
ALUMINUM 7049-T73511 EXTRUSIONS,2.8233E-09,7.0327E+04,2.6439E+04,6.8948E+04,0.3300,4.2748E+02,4.9642E+02,7.000,2.3400E-11,0.2000
ALUMINUM 7049-T75511 EXTRUSIONS,2.8233E-09,7.0327E+04,2.6439E+04,6.8948E+04,0.3300,4.7574E+02,5.3090E+02,7.000,2.3400E-11,0.2000
ALUMINUM 7050-T73652 HAND FORGING,2.7957E-09,7.1016E+04,2.6698E+04,6.9624E+04,0.3300,4.1369E+02,4.8263E+02,9.000,2.3400E-11,0.2000
ALUMINUM 7050-T736 DIE FORGINGS,2.7957E-09,7.1016E+04,2.6698E+04,6.9624E+04,0.3300,4.1369E+02,4.8263E+02,7.000,2.3400E-11,0.2000
ALUMINUM 7075-O SHEET,2.7957E-09,7.1016E+04,2.6698E+04,6.9624E+04,0.3300,1.0342E+02,2.2753E+02,17.000,2.3580E-11,0.2000
ALUMINUM 7075-T6 SHEET,2.7957E-09,7.1016E+04,2.6698E+04,6.9624E+04,0.3300,5.2400E+02,5.7226E+02,11.000,2.3580E-11,0.2000
ALUMINUM 7075-T651 PLATE,2.7957E-09,7.1705E+04,2.6957E+04,7.0300E+04,0.3300,5.2400E+02,5.8605E+02,10.000,2.3580E-11,0.2000
ALUMINUM 7075-T73 SHEET,2.7957E-09,7.1016E+04,2.6698E+04,6.9624E+04,0.3300,4.3437E+02,4.9642E+02,11.000,2.3580E-11,0.2000
ALUMINUM 7076-T61,2.8233E-09,6.6879E+04,2.5143E+04,6.5568E+04,0.3300,4.1369E+02,4.8263E+02,14.000,2.1600E-11,0.2000
ALUMINUM 7079-O SHEET,2.7403E-09,7.1705E+04,2.6957E+04,7.0300E+04,0.3300,1.0342E+02,2.2753E+02,17.000,2.3580E-11,0.2000
ALUMINUM 7079-T6 SHEET,2.7403E-09,7.1705E+04,2.6957E+04,7.0300E+04,0.3300,4.8263E+02,5.3090E+02,11.000,2.3580E-11,0.2000
ALUMINUM 7079-T651 PLATE,2.7403E-09,7.1705E+04,2.6957E+04,7.0300E+04,0.3300,5.3090E+02,5.7916E+02,10.000,2.3580E-11,0.2000
ALUMINUM 7178-O SHEET,2.8233E-09,7.1705E+04,2.6957E+04,7.0300E+04,0.3300,1.0342E+02,2.2753E+02,15.000,2.3400E-11,0.2000
ALUMINUM 7178-T6 SHEET,2.8233E-09,7.1705E+04,2.6957E+04,7.0300E+04,0.3300,5.1711E+02,5.7916E+02,11.000,2.3400E-11,0.2000
ALUMINUM 7178-T76 PLATE,2.8233E-09,7.0327E+04,2.6439E+04,6.8948E+04,0.3300,4.9642E+02,5.5848E+02,11.000,2.3400E-11,0.2000
ALUMINUM 7178-T651 PLATE,2.8233E-09,7.1705E+04,2.6957E+04,7.0300E+04,0.3300,5.7916E+02,6.4811E+02,9.000,2.3400E-11,0.2000
ALUMINUM WROUGHT 1060 O,2.7126E-09,6.8948E+04,2.5920E+04,6.7596E+04,0.3300,2.7579E+01,6.8948E+01,43.000,2.3580E-11,0.2000
ALUMINUM WROUGHT 1060 H14,2.7126E-09,6.8948E+04,2.5920E+04,6.7596E+04,0.3300,8.9632E+01,9.6527E+01,12.000,2.3580E-11,0.2000
ALUMINUM WROUGHT 1060 H18,2.7126E-09,6.8948E+04,2.5920E+04,6.7596E+04,0.3300,1.2411E+02,1.3100E+02,6.000,2.3580E-11,0.2000
ALUMINUM WROUGHT 1100 O,2.7126E-09,6.8948E+04,2.5920E+04,6.7596E+04,0.3300,3.4474E+01,8.9632E+01,35.000,2.3580E-11,0.2000
ALUMINUM WROUGHT 1100 H14,2.7126E-09,6.8948E+04,2.5920E+04,6.7596E+04,0.3300,1.1721E+02,1.2411E+02,9.000,2.3580E-11,0.2000
ALUMINUM WROUGHT 1100 H18,2.7126E-09,6.8948E+04,2.5920E+04,6.7596E+04,0.3300,1.5168E+02,1.6547E+02,5.000,2.3580E-11,0.2000
ALUMINUM WROUGHT 1350 O,2.7126E-09,6.8948E+04,2.5920E+04,6.7596E+04,0.3300,2.7579E+01,8.2737E+01,23.000,2.3760E-11,0.2000
ALUMINUM WROUGHT 1350 H19,2.7126E-09,6.8948E+04,2.5920E+04,6.7596E+04,0.3300,1.6547E+02,1.8616E+02,1.500,2.3760E-11,0.2000
ALUMINUM WROUGHT 2011 T3,3.0171E-09,7.0327E+04,2.6439E+04,6.8948E+04,0.3300,2.9647E+02,3.7921E+02,15.000,2.2860E-11,0.2000
ALUMINUM WROUGHT 2011 T8,3.0171E-09,7.0327E+04,2.6439E+04,6.8948E+04,0.3300,3.1026E+02,4.0679E+02,12.000,2.2860E-11,0.2000
ALUMINUM WROUGHT 2014 O,2.7957E-09,7.3084E+04,2.7475E+04,7.1651E+04,0.3300,9.6527E+01,1.6547E+02,18.000,2.3040E-11,0.2000
ALUMINUM WROUGHT 2014 T6,2.7957E-09,7.3084E+04,2.7475E+04,7.1651E+04,0.3300,4.6884E+02,5.1021E+02,10.000,2.3040E-11,0.2000
ALUMINUM WROUGHT 2017 O,2.7957E-09,7.2395E+04,2.7216E+04,7.0975E+04,0.3300,6.8948E+01,1.7926E+02,22.000,2.3580E-11,0.2000
ALUMINUM WROUGHT 2017 T4,2.7957E-09,7.2395E+04,2.7216E+04,7.0975E+04,0.3300,2.7579E+02,4.2748E+02,22.000,2.3580E-11,0.2000
ALUMINUM WROUGHT 2024 O,2.7957E-09,7.3084E+04,2.7475E+04,7.1651E+04,0.3300,7.5842E+01,1.8616E+02,22.000,2.3220E-11,0.2000
ALUMINUM WROUGHT 2024 T3,2.7957E-09,7.3084E+04,2.7475E+04,7.1651E+04,0.3300,3.4474E+02,4.8263E+02,18.000,2.3220E-11,0.2000
ALUMINUM WROUGHT 2024 T4 OR T351,2.7957E-09,7.3084E+04,2.7475E+04,7.1651E+04,0.3300,3.2405E+02,4.4816E+02,20.000,2.3220E-11,0.2000
ALUMINUM WROUGHT 2024 T361,2.7957E-09,7.3084E+04,2.7475E+04,7.1651E+04,0.3300,3.9300E+02,4.9642E+02,13.000,2.3220E-11,0.2000
ALUMINUM WROUGHT 2036 T4,2.7680E-09,7.1016E+04,2.6698E+04,6.9624E+04,0.3300,1.9305E+02,3.3784E+02,24.000,2.3400E-11,0.2000
ALUMINUM WROUGHT 2219 O,2.8510E-09,7.3084E+04,2.7475E+04,7.1651E+04,0.3300,7.5842E+01,1.7237E+02,18.000,2.2320E-11,0.2000
ALUMINUM WROUGHT 2219 T31 OR T351,2.8510E-09,7.3084E+04,2.7475E+04,7.1651E+04,0.3300,2.4821E+02,3.5853E+02,17.000,2.2320E-11,0.2000
ALUMINUM WROUGHT 2219 T81 OR T851,2.8510E-09,7.3084E+04,2.7475E+04,7.1651E+04,0.3300,3.5163E+02,4.5505E+02,10.000,2.2320E-11,0.2000
ALUMINUM WROUGHT 3003 O,2.7403E-09,6.8948E+04,2.5920E+04,6.7596E+04,0.3300,4.1369E+01,1.1032E+02,30.000,2.3220E-11,0.2000
ALUMINUM WROUGHT 3003 H12,2.7403E-09,6.8948E+04,2.5920E+04,6.7596E+04,0.3300,1.2411E+02,1.3100E+02,10.000,2.3220E-11,0.2000
ALUMINUM WROUGHT 3003 H14,2.7403E-09,6.8948E+04,2.5920E+04,6.7596E+04,0.3300,1.4479E+02,1.5168E+02,8.000,2.3220E-11,0.2000
ALUMINUM WROUGHT 3003 H18,2.7403E-09,6.8948E+04,2.5920E+04,6.7596E+04,0.3300,1.8616E+02,1.9995E+02,4.000,2.3220E-11,0.2000
ALUMINUM WROUGHT 3004 O,2.7126E-09,6.8948E+04,2.5920E+04,6.7596E+04,0.3300,6.8948E+01,1.7926E+02,20.000,2.3940E-11,0.2000
ALUMINUM WROUGHT 3004 H32,2.7126E-09,6.8948E+04,2.5920E+04,6.7596E+04,0.3300,1.7237E+02,2.1374E+02,10.000,2.3940E-11,0.2000
ALUMINUM WROUGHT 3004 H34,2.7126E-09,6.8948E+04,2.5920E+04,6.7596E+04,0.3300,1.9995E+02,2.4132E+02,9.000,2.3940E-11,0.2000
ALUMINUM WROUGHT 3004 H38,2.7126E-09,6.8948E+04,2.5920E+04,6.7596E+04,0.3300,2.4821E+02,2.8269E+02,5.000,2.3940E-11,0.2000
ALUMINUM WROUGHT 3105 O,2.7126E-09,6.8948E+04,2.5920E+04,6.7596E+04,0.3300,5.5158E+01,1.1721E+02,24.000,2.3580E-11,0.2000
ALUMINUM WROUGHT 3105 H14,2.7126E-09,6.8948E+04,2.5920E+04,6.7596E+04,0.3300,1.5168E+02,1.7237E+02,5.000,2.3580E-11,0.2000
ALUMINUM WROUGHT 3105 H18,2.7126E-09,6.8948E+04,2.5920E+04,6.7596E+04,0.3300,1.9305E+02,2.1374E+02,3.000,2.3580E-11,0.2000
ALUMINUM WROUGHT 3105 H25,2.7126E-09,6.8948E+04,2.5920E+04,6.7596E+04,0.3300,1.5858E+02,1.7926E+02,8.000,2.3580E-11,0.2000
ALUMINUM WROUGHT 4032 T6,2.6850E-09,7.8600E+04,2.9549E+04,7.7059E+04,0.3300,3.1716E+02,3.7921E+02,9.000,1.9440E-11,0.2000
ALUMINUM WROUGHT 5005 O,2.7126E-09,6.8948E+04,2.5920E+04,6.7596E+04,0.3300,4.1369E+01,1.2411E+02,25.000,2.3760E-11,0.2000
ALUMINUM WROUGHT 5005 H14,2.7126E-09,6.8948E+04,2.5920E+04,6.7596E+04,0.3300,1.5168E+02,1.5858E+02,6.000,2.3760E-11,0.2000
ALUMINUM WROUGHT 5005 H18,2.7126E-09,6.8948E+04,2.5920E+04,6.7596E+04,0.3300,1.9305E+02,1.9995E+02,4.000,2.3760E-11,0.2000
ALUMINUM WROUGHT 5005 H38,2.7126E-09,6.8948E+04,2.5920E+04,6.7596E+04,0.3300,1.8616E+02,1.9995E+02,5.000,2.3760E-11,0.2000
ALUMINUM WROUGHT 5050 O,2.6850E-09,6.8948E+04,2.5920E+04,6.7596E+04,0.3300,5.5158E+01,1.4479E+02,24.000,2.3760E-11,0.2000
ALUMINUM WROUGHT 5050 H34,2.6850E-09,6.8948E+04,2.5920E+04,6.7596E+04,0.3300,1.6547E+02,1.9305E+02,8.000,2.3760E-11,0.2000
ALUMINUM WROUGHT 5050 H38,2.6850E-09,6.8948E+04,2.5920E+04,6.7596E+04,0.3300,1.9995E+02,2.2063E+02,6.000,2.3760E-11,0.2000
ALUMINUM WROUGHT 5052 O,2.6850E-09,7.0327E+04,2.6439E+04,6.8948E+04,0.3300,8.9632E+01,1.9305E+02,25.000,2.3760E-11,0.2000
ALUMINUM WROUGHT 5052 H34,2.6850E-09,7.0327E+04,2.6439E+04,6.8948E+04,0.3300,2.1374E+02,2.6200E+02,10.000,2.3760E-11,0.2000
ALUMINUM WROUGHT 5052 H38,2.6850E-09,7.0327E+04,2.6439E+04,6.8948E+04,0.3300,2.5511E+02,2.8958E+02,7.000,2.3760E-11,0.2000
ALUMINUM WROUGHT 5083 O,2.6573E-09,7.1016E+04,2.6698E+04,6.9624E+04,0.3300,1.4479E+02,2.8958E+02,22.000,2.3760E-11,0.2000
ALUMINUM WROUGHT 5083 H321 OR H116,2.6573E-09,7.1016E+04,2.6698E+04,6.9624E+04,0.3300,2.2753E+02,3.1716E+02,16.000,2.3760E-11,0.2000
ALUMINUM WROUGHT 5086 0,2.6573E-09,7.1016E+04,2.6698E+04,6.9624E+04,0.3300,1.1721E+02,2.6200E+02,22.000,2.3760E-11,0.2000
ALUMINUM WROUGHT 5086 H32 OR H116,2.6573E-09,7.1016E+04,2.6698E+04,6.9624E+04,0.3300,2.0684E+02,2.8958E+02,12.000,2.3760E-11,0.2000
ALUMINUM WROUGHT 5154 O,2.6573E-09,7.0327E+04,2.6439E+04,6.8948E+04,0.3300,1.1721E+02,2.4132E+02,27.000,2.3940E-11,0.2000
ALUMINUM WROUGHT 5154 H34,2.6573E-09,7.0327E+04,2.6439E+04,6.8948E+04,0.3300,2.2753E+02,2.8958E+02,13.000,2.3940E-11,0.2000
ALUMINUM WROUGHT 5154 H38,2.6573E-09,7.0327E+04,2.6439E+04,6.8948E+04,0.3300,2.6890E+02,3.3095E+02,10.000,2.3940E-11,0.2000
ALUMINUM WROUGHT 5252 H25,2.6573E-09,6.8948E+04,2.5920E+04,6.7596E+04,0.3300,1.7237E+02,2.3442E+02,11.000,2.3760E-11,0.2000
ALUMINUM WROUGHT 5454 O,2.6850E-09,7.0327E+04,2.6439E+04,6.8948E+04,0.3300,1.1721E+02,2.4821E+02,22.000,2.3580E-11,0.2000
ALUMINUM WROUGHT 5454 H32,2.6850E-09,7.0327E+04,2.6439E+04,6.8948E+04,0.3300,2.0684E+02,2.7579E+02,10.000,2.3580E-11,0.2000
ALUMINUM WROUGHT 5454 H34,2.6850E-09,7.0327E+04,2.6439E+04,6.8948E+04,0.3300,2.4132E+02,3.0337E+02,10.000,2.3580E-11,0.2000
ALUMINUM WROUGHT 5456 O,2.6573E-09,7.1016E+04,2.6698E+04,6.9624E+04,0.3300,1.5858E+02,3.1026E+02,24.000,2.3940E-11,0.2000
ALUMINUM WROUGHT 5456 H24,2.6573E-09,7.1016E+04,2.6698E+04,6.9624E+04,0.3300,2.8269E+02,3.7232E+02,13.000,2.3940E-11,0.2000
ALUMINUM WROUGHT 5456 H34,2.6573E-09,7.1016E+04,2.6698E+04,6.9624E+04,0.3300,2.5511E+02,3.5163E+02,16.000,2.3940E-11,0.2000
ALUMINUM WROUGHT 5657 H25,2.6850E-09,6.8948E+04,2.5920E+04,6.7596E+04,0.3300,1.3790E+02,1.5858E+02,12.000,2.3760E-11,0.2000
ALUMINUM WROUGHT 5657 H38 OR H28,2.6850E-09,6.8948E+04,2.5920E+04,6.7596E+04,0.3300,1.6547E+02,1.9305E+02,7.000,2.3760E-11,0.2000
ALUMINUM WROUGHT 6061 O,2.7126E-09,6.8948E+04,2.5920E+04,6.7596E+04,0.3300,5.5158E+01,1.2411E+02,30.000,2.3580E-11,0.2000
ALUMINUM WROUGHT 6061 T451,2.7126E-09,6.8948E+04,2.5920E+04,6.7596E+04,0.3300,1.4479E+02,2.4132E+02,25.000,2.3580E-11,0.2000
ALUMINUM WROUGHT 6061 T651,2.7126E-09,6.8948E+04,2.5920E+04,6.7596E+04,0.3300,2.7579E+02,3.1026E+02,17.000,2.3580E-11,0.2000
ALUMINUM WROUGHT 6063 O,2.6850E-09,6.8948E+04,2.5920E+04,6.7596E+04,0.3300,4.8263E+01,8.9632E+01,25.000,2.3400E-11,0.2000
ALUMINUM WROUGHT 6063 T4,2.6850E-09,6.8948E+04,2.5920E+04,6.7596E+04,0.3300,8.9632E+01,1.7237E+02,22.000,2.3400E-11,0.2000
ALUMINUM WROUGHT 6063 T6,2.6850E-09,6.8948E+04,2.5920E+04,6.7596E+04,0.3300,2.1374E+02,2.4132E+02,12.000,2.3400E-11,0.2000
ALUMINUM WROUGHT 6066 O,2.7126E-09,6.8948E+04,2.5920E+04,6.7596E+04,0.3300,8.2737E+01,1.5168E+02,18.000,2.3220E-11,0.2000
ALUMINUM WROUGHT 6066 T4,2.7126E-09,6.8948E+04,2.5920E+04,6.7596E+04,0.3300,2.0684E+02,3.5853E+02,18.000,2.3220E-11,0.2000
ALUMINUM WROUGHT 6066 T6,2.7126E-09,6.8948E+04,2.5920E+04,6.7596E+04,0.3300,3.5853E+02,3.9300E+02,12.000,2.3220E-11,0.2000
ALUMINUM WROUGHT 6101 T6,2.6850E-09,6.8948E+04,2.5920E+04,6.7596E+04,0.3300,1.9305E+02,2.2063E+02,15.000,2.3400E-11,0.2000
ALUMINUM WROUGHT 7001 O,2.8510E-09,7.1016E+04,2.6698E+04,6.9624E+04,0.3300,1.5168E+02,2.5511E+02,14.000,2.3400E-11,0.2000
ALUMINUM WROUGHT 7001 T6,2.8510E-09,7.1016E+04,2.6698E+04,6.9624E+04,0.3300,6.2742E+02,6.7569E+02,9.000,2.3400E-11,0.2000
ALUMINUM WROUGHT 7075 O,2.7957E-09,7.1016E+04,2.6698E+04,6.9624E+04,0.3300,1.0342E+02,2.2753E+02,17.000,2.3580E-11,0.2000
ALUMINUM WROUGHT 7075 T6 OR T651,2.7957E-09,7.1016E+04,2.6698E+04,6.9624E+04,0.3300,5.0332E+02,5.7226E+02,11.000,2.3580E-11,0.2000
ALUMINUM WROUGHT 7075 T73,2.7957E-09,7.1016E+04,2.6698E+04,6.9624E+04,0.3300,4.3437E+02,4.9642E+02,11.000,2.3580E-11,0.2000
ALUMINUM WROUGHT 7178 O,2.8233E-09,7.1705E+04,2.6957E+04,7.0300E+04,0.3300,1.0342E+02,2.2753E+02,16.000,2.3400E-11,0.2000
ALUMINUM WROUGHT 7178 T6 OR T651,2.8233E-09,7.1705E+04,2.6957E+04,7.0300E+04,0.3300,5.3779E+02,6.0674E+02,11.000,2.3400E-11,0.2000
ALUMINUM WROUGHT 7178 T76 OR T7651,2.8233E-09,7.1705E+04,2.6957E+04,7.0300E+04,0.3300,5.0332E+02,5.7226E+02,11.000,2.3400E-11,0.2000
ACRYLIC LUCITE,1.1902E-09,2.9647E+03,1.0588E+03,4.9412E+03,0.4000,4.1369E+01,7.2395E+01,6.000,6.4800E-11,0.2000
BERYLLIUM S-65,1.8546E-09,2.8958E+05,1.4071E+05,1.0247E+05,0.0290,2.0684E+02,2.8958E+02,3.000,1.5840E-11,0.2000
BERYLLIUM S-200F,1.8546E-09,2.8958E+05,1.4071E+05,1.0247E+05,0.0290,2.4132E+02,3.2405E+02,2.000,1.5840E-11,0.2000
BERYLLIUM 1319,1.8546E-09,2.8958E+05,1.4071E+05,1.0247E+05,0.0290,2.4132E+02,3.4474E+02,3.000,1.5840E-11,0.2000
BERYLLIUM 1162,1.8546E-09,2.8958E+05,1.4071E+05,1.0247E+05,0.0290,1.7237E+02,2.6200E+02,1.000,1.5840E-11,0.2000
BERYLLIUM QMV,1.8546E-09,2.8958E+05,1.4071E+05,1.0247E+05,0.0290,2.0684E+02,3.4474E+02,5.000,1.5840E-11,0.2000
BERYLLIUM-COPPER 10 DEAD SOFT,8.8299E-09,1.3790E+05,5.2632E+04,1.2096E+05,0.3100,1.3790E+02,2.4132E+02,20.000,1.7640E-11,0.2000
BERYLLIUM-COPPER 10 PLANISHED,8.8299E-09,1.3790E+05,5.2632E+04,1.2096E+05,0.3100,1.7237E+02,2.4132E+02,20.000,1.7640E-11,0.2000
BERYLLIUM-COPPER 10 H TEMPER,8.8299E-09,1.3790E+05,5.2632E+04,1.2096E+05,0.3100,3.7921E+02,4.8263E+02,3.000,1.7640E-11,0.2000
BERYLLIUM-COPPER 10 AT TEMPER,8.8299E-09,1.3790E+05,5.2632E+04,1.2096E+05,0.3100,5.5158E+02,6.8948E+02,10.000,1.7640E-11,0.2000
BERYLLIUM-COPPER 10 HT TEMPER,8.8299E-09,1.3790E+05,5.2632E+04,1.2096E+05,0.3100,6.8948E+02,7.5842E+02,8.000,1.7640E-11,0.2000
BERYLLIUM-COPPER 10 HTR TEMPER,8.8299E-09,1.3790E+05,5.2632E+04,1.2096E+05,0.3100,7.5842E+02,8.2737E+02,1.000,1.7640E-11,0.2000
BERYLLIUM-COPPER 10 HTC TEMPER,8.8299E-09,1.3790E+05,5.2632E+04,1.2096E+05,0.3100,3.4474E+02,5.1711E+02,8.000,1.7640E-11,0.2000
BERYLLIUM-COPPER 25 DEAD SOFT,8.3593E-09,1.3100E+05,5.0000E+04,1.1491E+05,0.3100,1.9305E+02,4.1369E+02,35.000,1.7460E-11,0.2000
BERYLLIUM-COPPER 25 PLANISHED,8.3593E-09,1.3100E+05,5.0000E+04,1.1491E+05,0.3100,2.0684E+02,4.1369E+02,35.000,1.7460E-11,0.2000
BERYLLIUM-COPPER 25 1/4 H TEMPER,8.3593E-09,1.3100E+05,5.0000E+04,1.1491E+05,0.3100,4.1369E+02,5.1711E+02,10.000,1.7460E-11,0.2000
BERYLLIUM-COPPER 25 1/2 H TEMPER,8.3593E-09,1.3100E+05,5.0000E+04,1.1491E+05,0.3100,5.1711E+02,5.8605E+02,5.000,1.7460E-11,0.2000
BERYLLIUM-COPPER 25 H TEMPER,8.3593E-09,1.3100E+05,5.0000E+04,1.1491E+05,0.3100,6.2053E+02,6.8948E+02,2.000,1.7460E-11,0.2000
BERYLLIUM-COPPER 25 AT TEMPER,8.3593E-09,1.3100E+05,5.0000E+04,1.1491E+05,0.3100,9.6527E+02,1.1376E+03,4.000,1.7460E-11,0.2000
BERYLLIUM-COPPER 25 1/4 HT TEMPER,8.3593E-09,1.3100E+05,5.0000E+04,1.1491E+05,0.3100,1.0342E+03,1.2066E+03,3.000,1.7460E-11,0.2000
BERYLLIUM-COPPER 25 1/2 HT TEMPER,8.3593E-09,1.3100E+05,5.0000E+04,1.1491E+05,0.3100,1.1032E+03,1.2755E+03,2.000,1.7460E-11,0.2000
BERYLLIUM-COPPER 25 HT TEMPER,8.3593E-09,1.3100E+05,5.0000E+04,1.1491E+05,0.3100,1.1376E+03,1.3100E+03,2.000,1.7460E-11,0.2000
BRASS CARTRIDGE CU.7 ZN.3 1/2 HARD,8.5254E-09,1.1032E+05,4.1472E+04,1.0815E+05,0.3300,3.5853E+02,4.2748E+02,23.000,1.9980E-11,0.5000
BRASS CARTRIDGE CU.7 ZN.3 1/4 HARD,8.5254E-09,1.1032E+05,4.1472E+04,1.0815E+05,0.3300,2.7579E+02,3.7232E+02,43.000,1.9980E-11,0.5000
BRASS CARTRIDGE CU.7 ZN.3 ANNEALED,8.5254E-09,1.1032E+05,4.1472E+04,1.0815E+05,0.3300,1.3100E+02,3.5163E+02,55.000,1.9980E-11,0.5000
BRONZE COMMERCIAL CU.9 ZN.1 1/2 HARD,8.8022E-09,1.1721E+05,4.4064E+04,1.1491E+05,0.3300,3.1026E+02,3.5853E+02,15.000,1.8360E-11,0.5000
BRONZE COMMERCIAL CU.9 ZN.1 ANNEALED,8.8022E-09,1.1721E+05,4.4064E+04,1.1491E+05,0.3300,8.2737E+01,2.6200E+02,50.000,1.8360E-11,0.5000
COPPER COLD ROLLED,8.9129E-09,1.1721E+05,4.4064E+04,1.1491E+05,0.3300,3.1026E+02,3.4474E+02,6.000,1.7640E-11,0.5000
COPPER HOT ROLLED,8.9406E-09,1.1721E+05,4.4064E+04,1.1491E+05,0.3300,6.8948E+01,2.3442E+02,45.000,1.7640E-11,0.5000
COPPER OXYGEN FREE (99.92) ANNEALED,8.8852E-09,1.1721E+05,4.4064E+04,1.1491E+05,0.3300,6.8948E+01,2.2063E+02,45.000,1.7640E-11,0.5000
GOLD PURE (99.9) ANNEALED,1.9321E-08,8.2737E+04,2.9133E+04,1.7237E+05,0.4200,6.8948E+00,1.1721E+02,45.000,1.4040E-11,0.2000
GOLD PURE (99.9) COLD ROLLED,1.9321E-08,8.2737E+04,2.9133E+04,1.7237E+05,0.4200,2.0684E+02,2.2063E+02,4.000,1.4040E-11,0.2000
INCONEL X ANNEALED,8.3040E-09,2.1374E+05,8.0352E+04,2.0955E+05,0.3300,3.4474E+02,7.9290E+02,50.000,1.3680E-11,0.2000
INCONEL X HOT ROLLED,8.3040E-09,2.1374E+05,8.0352E+04,2.0955E+05,0.3300,8.2737E+02,1.2411E+03,25.000,1.3680E-11,0.2000
IRON GRAY CAST,7.1968E-09,8.9632E+04,3.4474E+04,7.4693E+04,0.3000,2.2063E+02,2.2132E+02,0.500,1.0800E-11,0.2000
IRON INGOT (99.9+) ANNEALED,7.8611E-09,2.0753E+05,8.0439E+04,1.6471E+05,0.2900,1.3100E+02,2.6200E+02,45.000,1.1700E-11,0.2000
IRON INGOT (99.9+) HOT ROLLED,7.8611E-09,2.0753E+05,8.0439E+04,1.6471E+05,0.2900,1.3100E+02,2.6200E+02,45.000,1.1700E-11,0.2000
IRON WROUGHT HAT ROLLED,7.6950E-09,1.9995E+05,7.7499E+04,1.5869E+05,0.2900,2.0684E+02,3.3095E+02,30.000,1.2060E-11,0.2000
LEAD PURE,1.1349E-08,1.3790E+04,4.8555E+03,2.8728E+04,0.4200,1.3100E+01,1.7237E+01,50.000,2.9520E-11,0.2000
MAGNESIUM AZ31B-H24,1.7715E-09,4.4816E+04,1.6598E+04,4.9795E+04,0.3500,1.5168E+02,2.5511E+02,21.000,2.6100E-11,0.2000
MAGNESIUM HK31B-H24,1.7992E-09,4.4126E+04,1.6343E+04,4.9029E+04,0.3500,1.9995E+02,2.5511E+02,8.000,2.5200E-11,0.2000
MAGNESIUM WROUGHT AZ31B 3-AL 1-ZN H24 SHEET 0.016/0.249,1.7798E-09,4.4816E+04,1.6848E+04,4.3937E+04,0.3300,2.2063E+02,2.8958E+02,15.000,2.6640E-11,0.2000
MAGNESIUM WROUGHT AZ31B 3-AL 1-ZN H24 SHEET 0.250/0.374,1.7798E-09,4.4816E+04,1.6848E+04,4.3937E+04,0.3300,1.9995E+02,2.7579E+02,17.000,2.6640E-11,0.2000
MAGNESIUM WROUGHT AZ31B 3-AL 1-ZN H24 SHEET 0.375/0.500,1.7798E-09,4.4816E+04,1.6848E+04,4.3937E+04,0.3300,1.8616E+02,2.6890E+02,19.000,2.6640E-11,0.2000
MAGNESIUM WROUGHT AZ31B 3-AL 1-ZN H24 SHEET 0.501/1.000,1.7798E-09,4.4816E+04,1.6848E+04,4.3937E+04,0.3300,1.6547E+02,2.6200E+02,17.000,2.6640E-11,0.2000
MAGNESIUM WROUGHT AZ31B 3-AL 1-ZN H24 SHEET 1.001/2.000,1.7798E-09,4.4816E+04,1.6848E+04,4.3937E+04,0.3300,1.5858E+02,2.5511E+02,14.000,2.6640E-11,0.2000
MAGNESIUM WROUGHT AZ31B 3-AL 1-ZN H24 SHEET 2.001/3.000,1.7798E-09,4.4816E+04,1.6848E+04,4.3937E+04,0.3300,1.4479E+02,2.5511E+02,16.000,2.6640E-11,0.2000
MAGNESIUM WROUGHT AZ31B 3-AL 1-ZN H26 SHEET 0.250/0.374,1.7798E-09,4.4816E+04,1.6848E+04,4.3937E+04,0.3300,2.0684E+02,2.7579E+02,16.000,2.6640E-11,0.2000
MAGNESIUM WROUGHT AZ31B 3-AL 1-ZN H26 SHEET 0.375/0.438,1.7798E-09,4.4816E+04,1.6848E+04,4.3937E+04,0.3300,1.9305E+02,2.7579E+02,13.000,2.6640E-11,0.2000
MAGNESIUM WROUGHT AZ31B 3-AL 1-ZN H26 SHEET 0.439/0.500,1.7798E-09,4.4816E+04,1.6848E+04,4.3937E+04,0.3300,1.9305E+02,2.7579E+02,13.000,2.6640E-11,0.2000
MAGNESIUM WROUGHT AZ31B 3-AL 1-ZN H26 SHEET 0.501/0.750,1.7798E-09,4.4816E+04,1.6848E+04,4.3937E+04,0.3300,1.9305E+02,2.7579E+02,10.000,2.6640E-11,0.2000
MAGNESIUM WROUGHT AZ31B 3-AL 1-ZN H26 SHEET 0.751/1.000,1.7798E-09,4.4816E+04,1.6848E+04,4.3937E+04,0.3300,1.7926E+02,2.6890E+02,10.000,2.6640E-11,0.2000
MAGNESIUM WROUGHT AZ31B 3-AL 1-ZN H26 SHEET 1.001/1.500,1.7798E-09,4.4816E+04,1.6848E+04,4.3937E+04,0.3300,1.7237E+02,2.6200E+02,10.000,2.6640E-11,0.2000
MAGNESIUM WROUGHT AZ31B 3-AL 1-ZN H26 SHEET 1.501/2.000,1.7798E-09,4.4816E+04,1.6848E+04,4.3937E+04,0.3300,1.6547E+02,2.6200E+02,10.000,2.6640E-11,0.2000
MAGNESIUM WROUGHT AZ31B 3-AL 1-ZN O   SHEET 0.016/0.060,1.7798E-09,4.4816E+04,1.6848E+04,4.3937E+04,0.3300,1.5168E+02,2.5511E+02,21.000,2.6640E-11,0.2000
MAGNESIUM WROUGHT AZ31B 3-AL 1-ZN O   SHEET 0.061/0.249,1.7798E-09,4.4816E+04,1.6848E+04,4.3937E+04,0.3300,1.5858E+02,2.5511E+02,21.000,2.6640E-11,0.2000
MAGNESIUM WROUGHT AZ31B 3-AL 1-ZN O   SHEET 0.250/0.500,1.7798E-09,4.4816E+04,1.6848E+04,4.3937E+04,0.3300,1.5168E+02,2.4821E+02,21.000,2.6640E-11,0.2000
MAGNESIUM WROUGHT AZ31B 3-AL 1-ZN O   SHEET 0.501/2.000,1.7798E-09,4.4816E+04,1.6848E+04,4.3937E+04,0.3300,1.5168E+02,2.4821E+02,17.000,2.6640E-11,0.2000
MAGNESIUM WROUGHT AZ31B 3-AL 1-ZN O   SHEET 2.001/3.000,1.7798E-09,4.4816E+04,1.6848E+04,4.3937E+04,0.3300,1.4479E+02,2.4821E+02,17.000,2.6640E-11,0.2000
MAGNESIUM WROUGHT HK31A 3.2-TH 0.7-ZR H24 SHEET 0.016/0.125,1.7909E-09,4.4816E+04,1.6848E+04,4.3937E+04,0.3300,2.0684E+02,2.6200E+02,9.000,2.6820E-11,0.2000
MAGNESIUM WROUGHT HK31A 3.2-TH 0.7-ZR H24 SHEET 0.126/0.250,1.7909E-09,4.4816E+04,1.6848E+04,4.3937E+04,0.3300,2.0684E+02,2.5511E+02,9.000,2.6820E-11,0.2000
MAGNESIUM WROUGHT HK31A 3.2-TH 0.7-ZR H24 SHEET 0.251/1.000,1.7909E-09,4.4816E+04,1.6848E+04,4.3937E+04,0.3300,2.1374E+02,2.6890E+02,14.000,2.6820E-11,0.2000
MAGNESIUM WROUGHT HK31A 3.2-TH 0.7-ZR H24 SHEET 1.001/3.000,1.7909E-09,4.4816E+04,1.6848E+04,4.3937E+04,0.3300,1.9995E+02,2.5511E+02,10.000,2.6820E-11,0.2000
MAGNESIUM WROUGHT HK31A 3.2-TH 0.7-ZR O   SHEET 0.016/0.250,1.7909E-09,4.4816E+04,1.6848E+04,4.3937E+04,0.3300,1.3790E+02,2.2753E+02,23.000,2.6820E-11,0.2000
MAGNESIUM WROUGHT HK31A 3.2-TH 0.7-ZR O   SHEET 0.251/0.500,1.7909E-09,4.4816E+04,1.6848E+04,4.3937E+04,0.3300,1.3100E+02,2.2753E+02,20.000,2.6820E-11,0.2000
MAGNESIUM WROUGHT HK31A 3.2-TH 0.7-ZR O   SHEET 0.501/1.000,1.7909E-09,4.4816E+04,1.6848E+04,4.3937E+04,0.3300,1.2411E+02,2.2753E+02,17.000,2.6820E-11,0.2000
MAGNESIUM WROUGHT HK31A 3.2-TH 0.7-ZR O   SHEET 1.001/3.000,1.7909E-09,4.4816E+04,1.6848E+04,4.3937E+04,0.3300,1.1721E+02,2.2063E+02,17.000,2.6820E-11,0.2000
MAGNESIUM WROUGHT HM21A 2.0-TH 0.8-MN T8  SHEET 0.016/0.250,1.7798E-09,4.4816E+04,1.6848E+04,4.3937E+04,0.3300,1.9305E+02,2.4821E+02,11.000,2.6820E-11,0.2000
MAGNESIUM WROUGHT HM21A 2.0-TH 0.8-MN T8  SHEET 0.251/0.500,1.7798E-09,4.4816E+04,1.6848E+04,4.3937E+04,0.3300,2.0684E+02,2.5511E+02,11.000,2.6820E-11,0.2000
MAGNESIUM WROUGHT HM21A 2.0-TH 0.8-MN T8  SHEET 0.501/1.000,1.7798E-09,4.4816E+04,1.6848E+04,4.3937E+04,0.3300,1.9305E+02,2.4132E+02,12.000,2.6820E-11,0.2000
MAGNESIUM WROUGHT HM21A 2.0-TH 0.8-MN T8  SHEET 1.001/2.000,1.7798E-09,4.4816E+04,1.6848E+04,4.3937E+04,0.3300,1.7237E+02,2.3442E+02,11.000,2.6820E-11,0.2000
MAGNESIUM WROUGHT HM21A 2.0-TH 0.8-MN T8  SHEET 2.001/3.000,1.7798E-09,4.4816E+04,1.6848E+04,4.3937E+04,0.3300,1.7926E+02,2.3442E+02,10.000,2.6820E-11,0.2000
MAGNESIUM WROUGHT HM21A 2.0-TH 0.8-MN T81 SHEET 0.125/0.312,1.7798E-09,4.4816E+04,1.6848E+04,4.3937E+04,0.3300,2.0684E+02,2.5511E+02,6.000,2.6820E-11,0.2000
MAGNESIUM WROUGHT AZ31B 3.0-AL 1.0-ZN TEMPER-F  EXTRUSION,1.7798E-09,4.4816E+04,1.6848E+04,4.3937E+04,0.3300,1.9305E+02,2.6200E+02,14.000,2.6640E-11,0.2000
MAGNESIUM WROUGHT AZ61A 6.5-AL 1.0-ZN TEMPER-F  EXTRUSION,1.7992E-09,4.4816E+04,1.6848E+04,4.3937E+04,0.3300,2.2753E+02,3.1026E+02,16.000,2.7180E-11,0.2000
MAGNESIUM WROUGHT AZ80A 8.5-AL 0.5-ZN TEMPER-F  EXTRUSION,1.7992E-09,4.4816E+04,1.6848E+04,4.3937E+04,0.3300,2.4821E+02,3.3784E+02,11.000,2.7180E-11,0.2000
MAGNESIUM WROUGHT AZ80A 8.5-AL 0.5-ZN TEMPER-T5 EXTRUSION,1.7992E-09,4.4816E+04,1.6848E+04,4.3937E+04,0.3300,2.7579E+02,3.7921E+02,7.000,2.7180E-11,0.2000
MAGNESIUM WROUGHT HM31A 3.25-TH 1.2-MN TEMPER-T5 EXTRUSION,1.8075E-09,4.4816E+04,1.6848E+04,4.3937E+04,0.3300,2.6890E+02,3.0337E+02,10.000,2.6820E-11,0.2000
MAGNESIUM WROUGHT ZK60A 5.5ZNH 0.45-ZR TEMPER-F  EXTRUSION,1.8296E-09,4.4816E+04,1.6848E+04,4.3937E+04,0.3300,2.7579E+02,3.3784E+02,14.000,2.7000E-11,0.2000
MAGNESIUM WROUGHT ZK60A 5.5ZNH 0.45-ZR TEMPER-T5 EXTRUSION,1.8296E-09,4.4816E+04,1.6848E+04,4.3937E+04,0.3300,3.0337E+02,3.6542E+02,14.000,2.7000E-11,0.2000
MAGNESIUM WROUGHT AZ31B 3.0-AL 1.0-ZN TEMPER-F  TUBING,1.7798E-09,4.4816E+04,1.6848E+04,4.3937E+04,0.3300,1.6547E+02,2.4821E+02,16.000,2.6640E-11,0.2000
MAGNESIUM WROUGHT AZ61A 6.5-AL 1.0-ZN TEMPER-F  TUBING,1.7992E-09,4.4816E+04,1.6848E+04,4.3937E+04,0.3300,1.6547E+02,2.8269E+02,14.000,2.7180E-11,0.2000
MAGNESIUM WROUGHT ZK60A 5.5ZNH 0.45-ZR TEMPER-F  TUBING,1.8296E-09,4.4816E+04,1.6848E+04,4.3937E+04,0.3300,2.3442E+02,3.1716E+02,12.000,2.7000E-11,0.2000
MAGNESIUM WROUGHT ZK60A 5.5ZNH 0.45-ZR TEMPER-T5 TUBING,1.8296E-09,4.4816E+04,1.6848E+04,4.3937E+04,0.3300,2.7579E+02,3.4474E+02,11.000,2.7000E-11,0.2000
MAGNESIUM WROUGHT AZ31B 3.0-AL 1.0-ZN TEMPER-F  FORGING,1.7798E-09,4.4816E+04,1.6848E+04,4.3937E+04,0.3300,1.9305E+02,2.6200E+02,9.000,2.6640E-11,0.2000
MAGNESIUM WROUGHT AZ61A 6.5-AL 1.0-ZN TEMPER-F  FORGING,1.7992E-09,4.4816E+04,1.6848E+04,4.3937E+04,0.3300,1.7926E+02,2.9647E+02,12.000,2.7180E-11,0.2000
MAGNESIUM WROUGHT AZ80A 8.5-AL 0.5-ZN TEMPER-F  FORGING,1.7992E-09,4.4816E+04,1.6848E+04,4.3937E+04,0.3300,2.1374E+02,3.1716E+02,8.000,2.7180E-11,0.2000
MAGNESIUM WROUGHT AZ80A 8.5-AL 0.5-ZN TEMPER-T5 FORGING,1.7992E-09,4.4816E+04,1.6848E+04,4.3937E+04,0.3300,2.3442E+02,3.4474E+02,6.000,2.7180E-11,0.2000
MAGNESIUM WROUGHT AZ80A 8.5-AL 0.5-ZN TEMPER-T6 FORGING,1.7992E-09,4.4816E+04,1.6848E+04,4.3937E+04,0.3300,2.4821E+02,3.4474E+02,5.000,2.7180E-11,0.2000
MAGNESIUM WROUGHT HM21A 2.0-TH 0.8-MN TEMPER-T5 FORGING,1.7798E-09,4.4816E+04,1.6848E+04,4.3937E+04,0.3300,1.5168E+02,2.3442E+02,9.000,2.6820E-11,0.2000
MAGNESIUM WROUGHT ZK60A 5.5ZNH 0.45-ZR TEMPER-T5 FORGING,1.8296E-09,4.4816E+04,1.6848E+04,4.3937E+04,0.3300,2.0684E+02,3.0337E+02,16.000,2.7000E-11,0.2000
MAGNESIUM WROUGHT ZK60A 5.5ZNH 0.45-ZR TEMPER-T6 FORGING,1.8296E-09,4.4816E+04,1.6848E+04,4.3937E+04,0.3300,2.6890E+02,3.2405E+02,11.000,2.7000E-11,0.2000
MAGNESIUM CAST AM100A 10.0-AL 0.3-ZN TEMPER-F,1.8103E-09,4.4816E+04,1.6848E+04,4.3937E+04,0.3300,8.2737E+01,1.5168E+02,2.000,,0.2000
MAGNESIUM CAST AM100A 10.0-AL 0.3-ZN TEMPER-T4,1.8103E-09,4.4816E+04,1.6848E+04,4.3937E+04,0.3300,8.9632E+01,2.7579E+02,10.000,,0.2000
MAGNESIUM CAST AM100A 10.0-AL 0.3-ZN TEMPER-T6,1.8103E-09,4.4816E+04,1.6848E+04,4.3937E+04,0.3300,1.1032E+02,2.7579E+02,4.000,,0.2000
MAGNESIUM CAST AM100A 10.0-AL 0.3-ZN TEMPER-T61,1.8103E-09,4.4816E+04,1.6848E+04,4.3937E+04,0.3300,1.5168E+02,2.7579E+02,2.000,,0.2000
MAGNESIUM CAST AZ63A  60.0-AL 3.0-ZN TEMPER-F,1.8352E-09,4.4816E+04,1.6848E+04,4.3937E+04,0.3300,9.6527E+01,1.9995E+02,6.000,,0.2000
MAGNESIUM CAST AZ63A  60.0-AL 3.0-ZN TEMPER-T4,1.8352E-09,4.4816E+04,1.6848E+04,4.3937E+04,0.3300,9.6527E+01,2.7579E+02,12.000,,0.2000
MAGNESIUM CAST AZ63A  60.0-AL 3.0-ZN TEMPER-T5,1.8352E-09,4.4816E+04,1.6848E+04,4.3937E+04,0.3300,1.0342E+02,1.9995E+02,4.000,,0.2000
MAGNESIUM CAST AZ63A  60.0-AL 3.0-ZN TEMPER-T6,1.8352E-09,4.4816E+04,1.6848E+04,4.3937E+04,0.3300,1.3100E+02,2.7579E+02,5.000,,0.2000
MAGNESIUM CAST AZ81A   7.5-AL 0.7-ZN TEMPER-T4,1.7992E-09,4.4816E+04,1.6848E+04,4.3937E+04,0.3300,8.2737E+01,2.7579E+02,15.000,,0.2000
MAGNESIUM CAST AZ91A   8.7-AL 0.7-ZN TEMPER-F,1.8103E-09,4.4816E+04,1.6848E+04,4.3937E+04,0.3300,9.6527E+01,1.6547E+02,2.500,,0.2000
MAGNESIUM CAST AZ91A   8.7-AL 0.7-ZN TEMPER-T4,1.8103E-09,4.4816E+04,1.6848E+04,4.3937E+04,0.3300,8.9632E+01,2.7579E+02,15.000,,0.2000
MAGNESIUM CAST AZ91A   8.7-AL 0.7-ZN TEMPER-T6,1.8103E-09,4.4816E+04,1.6848E+04,4.3937E+04,0.3300,1.3100E+02,2.7579E+02,5.000,,0.2000
MAGNESIUM CAST AZ92A   9.0-AL 2.0-ZN TEMPER-F,1.8186E-09,4.4816E+04,1.6848E+04,4.3937E+04,0.3300,9.6527E+01,1.6547E+02,2.000,,0.2000
MAGNESIUM CAST AZ92A   9.0-AL 2.0-ZN TEMPER-T4,1.8186E-09,4.4816E+04,1.6848E+04,4.3937E+04,0.3300,9.6527E+01,2.7579E+02,10.000,,0.2000
MAGNESIUM CAST AZ92A   9.0-AL 2.0-ZN TEMPER-T5,1.8186E-09,4.4816E+04,1.6848E+04,4.3937E+04,0.3300,1.1721E+02,1.7926E+02,1.000,,0.2000
MAGNESIUM CAST AZ92A   9.0-AL 2.0-ZN TEMPER-T6,1.8186E-09,4.4816E+04,1.6848E+04,4.3937E+04,0.3300,1.5168E+02,2.7579E+02,2.000,,0.2000
MAGNESIUM CAST EZ33A   2.5-RE 3.2-ZN TEMPER-T5,1.8269E-09,4.4816E+04,1.6848E+04,4.3937E+04,0.3300,1.1032E+02,1.5858E+02,3.000,,0.2000
MAGNESIUM CAST HK31A   3.2-TH 0.3-ZN TEMPER-T6,1.7881E-09,4.4816E+04,1.6848E+04,4.3937E+04,0.3300,1.0342E+02,2.2063E+02,8.000,,0.2000
MAGNESIUM CAST HZ32A   3.2-TH 2.1-ZN TEMPER-T5,1.8269E-09,4.4816E+04,1.6848E+04,4.3937E+04,0.3300,1.0342E+02,1.9995E+02,6.000,,0.2000
MAGNESIUM CAST K1A     0.7-ZR        TEMPER-F,1.7411E-09,4.4816E+04,1.6848E+04,4.3937E+04,0.3300,5.5158E+01,1.7926E+02,19.000,,0.2000
MAGNESIUM CAST QE22A 2.5-AG 2.2-RE 0.7-ZR TEMPER-T6,1.8103E-09,4.4816E+04,1.6848E+04,4.3937E+04,0.3300,1.9305E+02,2.6200E+02,3.000,,0.2000
MAGNESIUM CAST QH21A 2.5-AG 1-RE 1.1-TH 0.7-ZR TEMPER-T6,1.8186E-09,4.4816E+04,1.6848E+04,4.3937E+04,0.3300,2.0684E+02,2.7579E+02,4.000,,0.2000
MAGNESIUM CAST ZE41A 4.2-ZN 1.25-RE 0.7-ZR     TEMPER-T5,1.8186E-09,4.4816E+04,1.6848E+04,4.3937E+04,0.3300,1.3790E+02,2.0684E+02,3.500,,0.2000
MAGNESIUM CAST ZE63A 5.75-ZN 2.6-RE 0.7-ZR     TEMPER-T6,1.8601E-09,4.4816E+04,1.6848E+04,4.3937E+04,0.3300,1.9305E+02,3.0337E+02,10.000,,0.2000
MAGNESIUM CAST ZE62A 5.7-ZN 1.8-TH 0.75-ZR     TEMPER-T5,1.8518E-09,4.4816E+04,1.6848E+04,4.3937E+04,0.3300,1.7237E+02,2.7579E+02,6.000,,0.2000
MAGNESIUM CAST ZK51A 4.6-ZN 0.75-ZR  TEMPER-T5,1.8103E-09,4.4816E+04,1.6848E+04,4.3937E+04,0.3300,1.6547E+02,2.7579E+02,8.000,,0.2000
[...]
STEEL WROUGHT 4620 1 IN. BAR CARB. 1700F+ 1500F OQ+450F,7.8334E-09,2.0684E+05,8.0172E+04,1.6416E+05,0.2900,7.3084E+02,8.6184E+02,19.000,1.1700E-11,0.2000
STEEL WROUGHT 4620 1 IN. BAR CARB. 1700F+ OQ+450F,7.8334E-09,2.0684E+05,8.0172E+04,1.6416E+05,0.2900,8.5495E+02,9.6527E+02,16.000,1.1700E-11,0.2000
STEEL WROUGHT 4620 1 IN. BAR CARB. 1700F+ OQ+300F,7.8334E-09,2.0684E+05,8.0172E+04,1.6416E+05,0.2900,9.0321E+02,1.0066E+03,16.000,1.1700E-11,0.2000
STEEL WROUGHT 4820 1 IN. BAR ANNEALED,7.8611E-09,1.9995E+05,7.7499E+04,1.5869E+05,0.2900,4.6195E+02,6.8258E+02,23.000,1.1520E-11,0.2000
STEEL WROUGHT 4820 1 IN. BAR NORM,7.8611E-09,1.9995E+05,7.7499E+04,1.5869E+05,0.2900,4.8263E+02,7.5153E+02,24.000,1.1520E-11,0.2000
STEEL WROUGHT 4820 1 IN. BAR CARB. 1700F+ 1475F OQ+450F,7.8611E-09,1.9995E+05,7.7499E+04,1.5869E+05,0.2900,1.2755E+03,1.4134E+03,13.000,1.1520E-11,0.2000
STEEL WROUGHT 4820 1 IN. BAR CARB. 1700F+ OQ+450F,7.8611E-09,1.9995E+05,7.7499E+04,1.5869E+05,0.2900,1.1721E+03,1.3858E+03,13.000,1.1520E-11,0.2000
STEEL WROUGHT 4820 1 IN. BAR CARB. 1700F+ OQ+300F,7.8611E-09,1.9995E+05,7.7499E+04,1.5869E+05,0.2900,1.1445E+03,1.4134E+03,13.000,1.1520E-11,0.2000
STEEL WROUGHT 5140 1 IN. BAR ANNEALED,7.8334E-09,1.9995E+05,7.7499E+04,1.5869E+05,0.2900,2.8958E+02,5.7226E+02,29.000,1.2780E-11,0.2000
STEEL WROUGHT 5140 1 IN. BAR NORM,7.8334E-09,1.9995E+05,7.7499E+04,1.5869E+05,0.2900,4.7574E+02,7.9290E+02,23.000,1.2780E-11,0.2000
STEEL WROUGHT 5140 1 IN. BAR OQ+1200F,7.8334E-09,2.0684E+05,8.0172E+04,1.6416E+05,0.2900,6.5500E+02,7.5842E+02,25.000,1.2780E-11,0.2000
STEEL WROUGHT 5140 1 IN. BAR OQ+1000F,7.8334E-09,2.0684E+05,8.0172E+04,1.6416E+05,0.2900,9.2390E+02,1.0687E+03,17.000,1.2780E-11,0.2000
STEEL WROUGHT 5140 1 IN. BAR OQ+800F,7.8334E-09,2.0684E+05,8.0172E+04,1.6416E+05,0.2900,1.1652E+03,1.3100E+03,12.000,1.2780E-11,0.2000
STEEL WROUGHT 5140 1 IN. BAR OQ+400F,7.8334E-09,2.0684E+05,8.0172E+04,1.6416E+05,0.2900,1.6410E+03,1.7926E+03,9.000,1.2780E-11,0.2000
STEEL WROUGHT 6150 1 IN. BAR ANNEALED,7.8334E-09,1.9995E+05,7.7499E+04,1.5869E+05,0.2900,4.1369E+02,6.6879E+02,23.000,1.2420E-11,0.2000
STEEL WROUGHT 6150 1 IN. BAR NORM,7.8334E-09,1.9995E+05,7.7499E+04,1.5869E+05,0.2900,6.1363E+02,9.3769E+02,22.000,1.2420E-11,0.2000
STEEL WROUGHT 6150 1 IN. BAR OQ+1200F,7.8334E-09,2.0684E+05,8.0172E+04,1.6416E+05,0.2900,8.9632E+02,9.7216E+02,19.000,1.2420E-11,0.2000
STEEL WROUGHT 6150 1 IN. BAR OQ+1000F,7.8334E-09,2.0684E+05,8.0172E+04,1.6416E+05,0.2900,1.1583E+03,1.1928E+03,14.000,1.2420E-11,0.2000
STEEL WROUGHT 6150 1 IN. BAR OQ+400F,7.8334E-09,2.0684E+05,8.0172E+04,1.6416E+05,0.2900,1.6892E+03,1.9305E+03,8.000,1.2420E-11,0.2000
STEEL WROUGHT 8630 1 IN. BAR ANNEALED,7.8334E-09,2.0684E+05,8.0172E+04,1.6416E+05,0.2900,3.7232E+02,5.6537E+02,29.000,1.1340E-11,0.2000
STEEL WROUGHT 8630 1 IN. BAR NORM,7.8334E-09,2.0684E+05,8.0172E+04,1.6416E+05,0.2900,4.2748E+02,6.4811E+02,24.000,1.1340E-11,0.2000
STEEL WROUGHT 8630 1 IN. BAR WQ+1200F,7.8334E-09,2.0684E+05,8.0172E+04,1.6416E+05,0.2900,6.8948E+02,7.9290E+02,23.000,1.1340E-11,0.2000
STEEL WROUGHT 8630 1 IN. BAR WQ+1000F,7.8334E-09,2.0684E+05,8.0172E+04,1.6416E+05,0.2900,8.4806E+02,9.3079E+02,19.000,1.1340E-11,0.2000
STEEL WROUGHT 8630 1 IN. BAR WQ+900F,7.8334E-09,2.0684E+05,8.0172E+04,1.6416E+05,0.2900,9.1011E+02,1.0135E+03,16.000,1.1340E-11,0.2000
STEEL WROUGHT 8630 1 IN. BAR WQ+400F,7.8334E-09,2.0684E+05,8.0172E+04,1.6416E+05,0.2900,1.2273E+03,1.3790E+03,9.000,1.1340E-11,0.2000
STEEL WROUGHT 8650 1 IN. BAR ANNEALED,7.8334E-09,1.9995E+05,7.7499E+04,1.5869E+05,0.2900,3.8611E+02,7.1705E+02,22.000,1.1700E-11,0.2000
STEEL WROUGHT 8650 1 IN. BAR NORM,7.8334E-09,1.9995E+05,7.7499E+04,1.5869E+05,0.2900,6.8948E+02,1.0273E+03,14.000,1.1700E-11,0.2000
STEEL WROUGHT 8650 1 IN. BAR WQ+1200F,7.8334E-09,1.9995E+05,7.7499E+04,1.5869E+05,0.2900,8.5495E+02,9.3769E+02,17.000,1.1700E-11,0.2000
STEEL WROUGHT 8650 1 IN. BAR WQ+1000F,7.8334E-09,1.9995E+05,7.7499E+04,1.5869E+05,0.2900,1.0687E+03,1.2135E+03,14.000,1.1700E-11,0.2000
STEEL WROUGHT 8650 1 IN. BAR WQ+400F,7.8334E-09,1.9995E+05,7.7499E+04,1.5869E+05,0.2900,1.6754E+03,1.9374E+03,10.000,1.1700E-11,0.2000
STEEL WROUGHT HY140 1 IN. PLATE(L) Q+TEMPER 1000F,7.8888E-09,2.0340E+05,7.8835E+04,1.6142E+05,0.2900,9.7906E+02,1.0273E+03,20.000,1.3140E-11,0.2000
STEEL WROUGHT HY140 1 IN. PLATE(T) Q+TEMPER 1000F,7.8888E-09,2.0340E+05,7.8835E+04,1.6142E+05,0.2900,9.7906E+02,1.0273E+03,20.000,1.3140E-11,0.2000
STEEL WROUGHT HY140 1 IN. PLATE WELD+TEMPER 1000F,7.8888E-09,2.0340E+05,7.8835E+04,1.6142E+05,0.2900,9.9285E+02,1.1238E+03,18.000,1.3140E-11,0.2000
STEEL WROUGHT H-11 (VM) BAR Q+T,7.7781E-09,2.0684E+05,8.0172E+04,1.6416E+05,0.2900,1.4479E+03,1.7926E+03,8.000,1.1340E-11,0.2000
STEEL WROUGHT H-11 (VM) BAR Q+T 1050F,7.7781E-09,2.0684E+05,8.0172E+04,1.6416E+05,0.2900,1.5858E+03,1.9305E+03,10.000,1.1340E-11,0.2000
STEEL WROUGHT H-11 (VM) SHEET Q+T,7.7781E-09,1.9995E+05,7.7499E+04,1.5869E+05,0.2900,1.4479E+03,1.7926E+03,4.000,1.1340E-11,0.2000
STEEL WROUGHT H-11 (VM) SHEET Q+T 1050F,7.7781E-09,1.9443E+05,7.5361E+04,1.5431E+05,0.2900,1.5168E+03,1.9305E+03,4.000,1.1340E-11,0.2000
STEEL WROUGHT D6AC PLATE(L) TEMPER 500F,7.8611E-09,2.1029E+05,8.1508E+04,1.6690E+05,0.2900,1.7237E+03,1.9995E+03,9.000,1.3320E-11,0.2000
STEEL WROUGHT D6AC PLATE(L) TEMPER 1000F,7.8611E-09,2.1029E+05,8.1508E+04,1.6690E+05,0.2900,1.4824E+03,1.5858E+03,10.000,1.3320E-11,0.2000
STEEL WROUGHT D6AC SHEET TEMPER 500F,7.8611E-09,2.1029E+05,8.1508E+04,1.6690E+05,0.2900,1.5858E+03,1.9995E+03,5.000,1.3320E-11,0.2000
STEEL WROUGHT D6AC SHEET TEMPER 1000F,7.8611E-09,2.1029E+05,8.1508E+04,1.6690E+05,0.2900,1.3790E+03,1.5168E+03,6.000,1.3320E-11,0.2000
STEEL WROUGHT 9NI-4CO-25 PLATE TEMPER 600F,7.8611E-09,1.9512E+05,7.5629E+04,1.5486E+05,0.2900,1.3445E+03,1.4824E+03,9.000,1.1520E-11,0.2000
STEEL WROUGHT 9NI-4CO-25 PLATE TEMPER 1000F,7.8611E-09,1.9650E+05,7.6163E+04,1.5595E+05,0.2900,1.3100E+03,1.3790E+03,17.000,1.1520E-11,0.2000
STEEL WROUGHT 9NI-4CO-25 SHEET TEMPER 600F,7.8611E-09,1.9512E+05,7.5629E+04,1.5486E+05,0.2900,1.3790E+03,1.5168E+03,10.000,1.1520E-11,0.2000
STEEL WROUGHT 9NI-4CO-25 PLATE TEMPER 1000F,7.8611E-09,1.9650E+05,7.6163E+04,1.5595E+05,0.2900,1.2755E+03,1.4134E+03,15.000,1.1520E-11,0.2000
STEEL WROUGHT 9NI-4CO-45 PLATE TEMPER 600F,7.7504E-09,1.9512E+05,7.5629E+04,1.5486E+05,0.2900,1.7582E+03,1.9305E+03,5.000,1.1160E-11,0.2000
STEEL WROUGHT 9NI-4CO-45 PLATE TEMPER 1000F,7.7504E-09,1.9650E+05,7.6163E+04,1.5595E+05,0.2900,1.4134E+03,1.4824E+03,9.000,1.1160E-11,0.2000
STEEL WROUGHT 9NI-4CO-45 SHEET TEMPER 600F,7.7504E-09,1.9512E+05,7.5629E+04,1.5486E+05,0.2900,1.5858E+03,1.7926E+03,5.000,1.1160E-11,0.2000
STEEL WROUGHT 9NI-4CO-45 PLATE TEMPER 1000F,7.7504E-09,1.9650E+05,7.6163E+04,1.5595E+05,0.2900,1.3790E+03,1.4479E+03,9.000,1.1160E-11,0.2000
STEEL WROUGHT 18NI-MIRAGE 200 PLATE(T) ANNEALED,7.9995E-09,1.9857E+05,7.6965E+04,1.5759E+05,0.2900,7.5842E+02,9.6527E+02,18.000,1.0080E-11,0.2000
STEEL WROUGHT 18NI-MIRAGE 200 PLATE(T) AGE 900F,7.9995E-09,1.9857E+05,7.6965E+04,1.5759E+05,0.2900,1.5513E+03,1.6203E+03,12.000,1.0080E-11,0.2000
STEEL WROUGHT 18NI-MIRAGE 200 PLATE(L) AGE 900F,7.9995E-09,1.8823E+05,7.2956E+04,1.4939E+05,0.2900,1.4824E+03,1.5513E+03,11.000,1.0080E-11,0.2000
STEEL WROUGHT 18NI-MIRAGE 200 WELDED AGE 900F,7.9995E-09,1.8823E+05,7.2956E+04,1.4939E+05,0.2900,1.4824E+03,1.5168E+03,7.000,1.0080E-11,0.2000
STEEL WROUGHT 18NI-MIRAGE 250 (VM) PLATE(T) ANNEALED,8.0272E-09,1.7582E+05,6.8146E+04,1.3954E+05,0.2900,8.9632E+02,1.0342E+03,18.000,1.0080E-11,0.2000
STEEL WROUGHT 18NI-MIRAGE 250 (VM) PLATE(T) AGE 900F,8.0272E-09,1.7582E+05,6.8146E+04,1.3954E+05,0.2900,1.5651E+03,1.6341E+03,12.000,1.0080E-11,0.2000
STEEL WROUGHT 18NI-MIRAGE 250 (VM) PLATE(L) AGE 900F,8.0272E-09,1.7788E+05,6.8948E+04,1.4118E+05,0.2900,1.6341E+03,1.7651E+03,11.000,1.0080E-11,0.2000
STEEL WROUGHT 18NI-MIRAGE 250 (VM) SHEET(T) AGE 900F,8.0272E-09,1.7513E+05,6.7879E+04,1.3899E+05,0.2900,1.8133E+03,1.8547E+03,3.100,1.0080E-11,0.2000
STEEL WROUGHT 18NI-MIRAGE 300 (VM) PLATE(T) ANNEALED,8.0272E-09,1.8892E+05,7.3223E+04,1.4993E+05,0.2900,8.2737E+02,1.0480E+03,19.000,8.6400E-12,0.2000
STEEL WROUGHT 18NI-MIRAGE 300 (VM) PLATE(T) AGE 900F,8.0272E-09,1.8892E+05,7.3223E+04,1.4993E+05,0.2900,1.9098E+03,1.9788E+03,6.700,8.6400E-12,0.2000
STEEL WROUGHT 18NI-MIRAGE 300 (VM) PLATE(L) AGE 900F,8.0272E-09,1.7995E+05,6.9749E+04,1.4282E+05,0.2900,1.9236E+03,1.9857E+03,7.000,8.6400E-12,0.2000
STEEL WROUGHT 18NI-MIRAGE 300 (VM) SHEET(T) AGE 900F,8.0272E-09,1.8478E+05,7.1620E+04,1.4665E+05,0.2900,1.8754E+03,1.9581E+03,3.500,8.6400E-12,0.2000
STEEL WROUGHT 18NI-MIRAGE 350 (VM) 5/8 BAR ANNEALED,8.0825E-09,1.8616E+05,7.2154E+04,1.4774E+05,0.2900,8.2737E+02,1.1376E+03,18.000,1.1340E-11,0.2000
STEEL WROUGHT 18NI-MIRAGE 350 (VM) 5/8 BAR AGE 900F,8.0825E-09,1.8616E+05,7.2154E+04,1.4774E+05,0.2900,2.3028E+03,2.3511E+03,10.000,1.1340E-11,0.2000
STEEL WROUGHT 18NI-MIRAGE 350 (VM) 1/2 PLATE(T) AGE 900F,8.0825E-09,1.8616E+05,7.2154E+04,1.4774E+05,0.2900,2.3787E+03,2.4270E+03,8.500,1.1340E-11,0.2000
STEEL WROUGHT 18NI-MIRAGE 350 (VM) SHEET(T) AGE 900F,8.0825E-09,1.8616E+05,7.2154E+04,1.4774E+05,0.2900,2.5097E+03,2.5717E+03,4.000,1.1340E-11,0.2000
TANTALUM PURE ANNEALED SHEET,1.6608E-08,1.8616E+05,6.8948E+04,2.0684E+05,0.3500,2.4132E+02,3.1026E+02,30.000,6.4260E-12,0.2000
TEFLON,2.2006E-09,4.2403E+02,1.4622E+02,1.4134E+03,0.4500,8.2737E+00,1.2411E+01,100.000,9.9000E-11,0.2000
TITANIUM COMMERCIAL PURE ANNEALED,4.5118E-09,1.1376E+05,4.3755E+04,9.4803E+04,0.3000,4.8263E+02,6.2053E+02,23.000,9.0000E-12,0.2000
TITANIUM WROUGHT UNALLOYED GRADE 1 ANNEALED,4.5118E-09,1.0204E+05,3.8076E+04,1.0629E+05,0.3400,2.4132E+02,3.3095E+02,30.000,8.6400E-12,0.2000
TITANIUM WROUGHT UNALLOYED GRADE 2 ANNEALED,4.5118E-09,1.0273E+05,3.8333E+04,1.0701E+05,0.3400,3.4474E+02,4.3437E+02,28.000,8.6400E-12,0.2000
TITANIUM WROUGHT UNALLOYED GRADE 3 ANNEALED,4.5118E-09,1.0342E+05,3.8590E+04,1.0773E+05,0.3400,4.4816E+02,5.1711E+02,25.000,8.6400E-12,0.2000
TITANIUM WROUGHT UNALLOYED GRADE 4 ANNEALED,4.5118E-09,1.0411E+05,3.8847E+04,1.0845E+05,0.3400,5.8605E+02,6.5500E+02,20.000,8.6400E-12,0.2000
TITANIUM WROUGHT 0.2PB GRADE 7 ANNEALED,4.5118E-09,1.0273E+05,3.8333E+04,1.0701E+05,0.3400,3.4474E+02,4.3437E+02,28.000,8.6400E-12,0.2000
TITANIUM WROUGHT CODE 12 ANNEALED,4.5395E-09,1.0342E+05,3.7472E+04,1.4364E+05,0.3800,4.8263E+02,6.2053E+02,23.000,9.9000E-12,0.2000
TITANIUM WROUGHT 5-AL 2.5-SN ANNEALED,4.4841E-09,1.0894E+05,4.0648E+04,1.1348E+05,0.3400,7.9290E+02,8.2737E+02,13.000,9.3600E-12,0.2000
TITANIUM WROUGHT 5-AL 2.5-SN ELI ANNEALED,4.4841E-09,1.1032E+05,4.1163E+04,1.1491E+05,0.3400,6.8948E+02,7.5842E+02,17.000,9.3600E-12,0.2000
TITANIUM WROUGHT 3-AL 2.5-V ANNEALED,4.4841E-09,9.9974E+04,3.7304E+04,1.0414E+05,0.3400,6.2053E+02,6.5500E+02,22.000,9.5400E-12,0.2000
TITANIUM WROUGHT 6-AL 2-CB 1-TA 1-MO ANNEALED,4.4841E-09,1.1583E+05,4.4211E+04,1.0161E+05,0.3100,7.5842E+02,8.6184E+02,14.000,9.1800E-12,0.2000
TITANIUM WROUGHT 8-AL 1-MO 1-V ANNEALED,4.3734E-09,1.2066E+05,4.5704E+04,1.1172E+05,0.3200,9.3079E+02,9.9974E+02,12.000,8.6400E-12,0.2000
TITANIUM WROUGHT 4.5-AL 5-MO 1.5-CR CRONA5,4.5395E-09,1.1170E+05,4.1677E+04,1.1635E+05,0.3400,9.3079E+02,9.6527E+02,12.000,9.0000E-12,0.2000
TITANIUM WROUGHT 5-AL 2-SN 2-ZR 4-MO 4-CR ANNEALED,4.6502E-09,1.1238E+05,4.2570E+04,1.0406E+05,0.3200,1.0687E+03,1.1376E+03,8.000,9.3600E-12,0.2000
TITANIUM 6-AL 4-V ANNEALED,4.4565E-09,1.1376E+05,4.3755E+04,9.4803E+04,0.3000,8.9632E+02,9.3079E+02,15.000,1.0260E-11,0.2000
TITANIUM 6-AL 4-V HEAT-TREATED,4.4565E-09,1.1376E+05,4.3755E+04,9.4803E+04,0.3000,9.9974E+02,1.0687E+03,12.000,1.0260E-11,0.2000
TITANIUM WROUGHT 6-AL 4-V AGED,4.4288E-09,1.1376E+05,4.2449E+04,1.1850E+05,0.3400,1.1032E+03,1.1721E+03,12.000,9.0000E-12,0.2000
TITANIUM WROUGHT 6-AL 4-V ELI ANNEALED,4.4288E-09,1.1032E+05,4.1163E+04,1.1491E+05,0.3400,8.2737E+02,9.3079E+02,10.000,8.6400E-12,0.2000
TITANIUM WROUGHT 6-AL 6-V 2-SN ANNEALED,4.5395E-09,1.1032E+05,4.1786E+04,1.0214E+05,0.3200,9.9974E+02,1.0687E+03,14.000,9.1800E-12,0.2000
TITANIUM WROUGHT 6-AL 6-V 2-SN AGED,4.5395E-09,1.1721E+05,4.4398E+04,1.0853E+05,0.3200,1.2066E+03,1.2755E+03,10.000,9.1800E-12,0.2000
TITANIUM WROUGHT 6-AL 2-SN 4-ZR 2-MO ANNEALED,4.5395E-09,1.1376E+05,4.3092E+04,1.0534E+05,0.3200,9.1700E+02,9.9974E+02,15.000,7.7400E-12,0.2000
TITANIUM WROUGHT 6-AL 2-SN 4-ZR 6-MO ANNEALED,4.6502E-09,1.1376E+05,4.3092E+04,1.0534E+05,0.3200,9.6527E+02,1.0342E+03,11.000,9.0000E-12,0.2000
TITANIUM WROUGHT 6-AL 2-SN 4-ZR 6-MO ANNEALED,4.6502E-09,1.1376E+05,4.3092E+04,1.0534E+05,0.3200,1.1376E+03,1.2066E+03,8.000,9.0000E-12,0.2000
TITANIUM WROUGHT 6-AL 2-SN 2-ZR 2-MO 2-CR 0.25-SI,4.4841E-09,1.0825E+05,4.1003E+04,1.0023E+05,0.3200,1.0135E+03,1.1170E+03,14.000,9.1800E-12,0.2000
TITANIUM WROUGHT 10-V 2-FE 3-AL ANNEALED,4.6502E-09,1.0963E+05,4.1525E+04,1.0151E+05,0.3200,8.9632E+02,9.6527E+02,9.000,9.7200E-12,0.2000
TITANIUM WROUGHT 10-V 2-FE 3-AL AGED,4.6502E-09,1.0963E+05,4.1525E+04,1.0151E+05,0.3200,1.1376E+03,1.2411E+03,7.000,9.7200E-12,0.2000
TITANIUM WROUGHT 15-V 3-CR 3-SN 3-AL SOLUTION ANNEALED,4.7609E-09,8.2737E+04,3.1340E+04,7.6608E+04,0.3200,7.7221E+02,7.9290E+02,20.000,8.4600E-12,0.2000
TITANIUM WROUGHT 15-V 3-CR 3-SN 3-AL AGED,4.7609E-09,9.8595E+04,3.7347E+04,9.1292E+04,0.3200,1.0687E+03,1.1376E+03,8.000,8.4600E-12,0.2000
TITANIUM WROUGHT 13-V 11-CR 3-AL ANNEALED,4.8440E-09,9.8595E+04,3.7921E+04,8.2163E+04,0.3000,8.6184E+02,9.3079E+02,18.000,9.3600E-12,0.2000
TITANIUM WROUGHT 13-V 11-CR 3-AL AGED,4.8440E-09,1.1032E+05,4.2429E+04,9.1930E+04,0.3000,1.1376E+03,1.2066E+03,7.000,9.3600E-12,0.2000
TITANIUM WROUGHT 3-AL 8-V 6-CR 4-MO 4-ZR ANNEALED,4.8163E-09,1.0342E+05,3.8880E+04,1.0139E+05,0.3300,7.7911E+02,8.2737E+02,10.000,8.8200E-12,0.2000
TITANIUM WROUGHT 3-AL 8-V 6-CR 4-MO 4-ZR AGED,4.8163E-09,1.0342E+05,3.8880E+04,1.0139E+05,0.3300,1.1721E+03,1.2411E+03,7.000,8.8200E-12,0.2000
TITANIUM WROUGHT 4.5-SN 6-ZR 11.5-MO BETA III ANNEALED,5.0654E-09,8.2737E+04,3.0418E+04,9.8497E+04,0.3600,6.5500E+02,6.8948E+02,23.000,7.5600E-12,0.2000
TITANIUM WROUGHT 4.5-SN 6-ZR 11.5-MO BETA III AGED,5.0654E-09,1.0342E+05,3.8880E+04,1.0139E+05,0.3300,1.1721E+03,1.2411E+03,7.000,7.5600E-12,0.2000
TUNGSTEN DRAWN 15 MIN.,1.9293E-08,3.4474E+05,1.3466E+05,2.6117E+05,0.2800,1.9650E+03,1.9719E+03,1.000,3.9600E-12,0.2000
TUNGSTEN SINTERED,1.9293E-08,3.4474E+05,1.3466E+05,2.6117E+05,0.2800,1.2755E+02,1.2824E+02,1.000,3.9600E-12,0.2000
TUNGSTEN NICKEL IRON,1.8269E-08,4.2334E+05,1.7639E+05,2.3519E+05,0.2000,6.7569E+02,8.8253E+02,29.000,1.6920E-11,0.2000
URANIUM 6NI - BINARY,1.7494E-08,6.2053E+04,2.2983E+04,6.8948E+04,0.3500,4.2058E+02,8.4806E+02,30.000,1.6920E-11,0.2000
URANIUM BETA QUENCHED,1.8869E-08,1.7237E+05,6.8948E+04,1.1491E+05,0.2500,3.4474E+02,7.5842E+02,25.000,1.4940E-11,0.2000
URANIUM D-38,1.8961E-08,1.7926E+05,7.1705E+04,1.1951E+05,0.2500,1.7237E+02,3.7921E+02,20.000,1.4940E-11,0.2000
URANIUM 0.75 TI,1.8529E-08,1.5306E+05,6.1225E+04,1.0204E+05,0.2500,9.9560E+02,1.2755E+03,20.000,1.4940E-11,0.2000
VANADIUM PURE ANNEALED,6.0896E-09,1.2824E+05,4.9324E+04,1.0687E+05,0.3000,1.2411E+02,1.7513E+02,26.000,1.6740E-11,0.2000
STEEL WROUGHT 4340 1 IN. BAR ANNEALED,7.8334E-09,2.0684E+05,8.0172E+04,1.6416E+05,0.2900,4.7574E+02,7.4463E+02,22.000,1.1340E-11,0.2000
STEEL WROUGHT 4340 CASE 1,7.8334E-09,2.0684E+05,8.0172E+04,1.6416E+05,0.2900,6.2053E+02,8.1220E+02,21.400,1.1340E-11,0.2000
STEEL WROUGHT 4340 CASE 2,7.8334E-09,2.0684E+05,8.0172E+04,1.6416E+05,0.2900,8.8253E+02,9.8733E+02,18.400,1.1340E-11,0.2000
STEEL WROUGHT 4340 1 IN. BAR OQ+1200F,7.8334E-09,2.0684E+05,8.0172E+04,1.6416E+05,0.2900,9.1700E+02,1.0135E+03,18.000,1.1340E-11,0.2000
STEEL WROUGHT 4340 CASE 3,7.8334E-09,2.0684E+05,8.0172E+04,1.6416E+05,0.2900,9.3079E+02,1.0280E+03,17.700,1.1340E-11,0.2000
STEEL WROUGHT 4340 CASE 4,7.8334E-09,2.0684E+05,8.0172E+04,1.6416E+05,0.2900,1.0342E+03,1.1252E+03,16.800,1.1340E-11,0.2000
STEEL WROUGHT 4340,7.8611E-09,2.0477E+05,7.9370E+04,1.6252E+05,0.2900,1.0963E+03,1.1376E+03,16.500,1.2294E-11,0.2000
STEEL WROUGHT 4340 1 IN. BAR OQ+1200F,7.8334E-09,2.0684E+05,8.0172E+04,1.6416E+05,0.2900,1.1721E+03,1.2617E+03,14.000,1.1340E-11,0.2000
STEEL WROUGHT 4340 CASE 5,7.8334E-09,2.0684E+05,8.0172E+04,1.6416E+05,0.2900,1.2755E+03,1.3996E+03,12.900,1.1340E-11,0.2000
STEEL 4340 AISI OQ 1000F 0.5 ROUND,7.8611E-09,2.0477E+05,7.9370E+04,1.6252E+05,0.2900,1.1652E+03,1.2548E+03,13.700,1.1340E-11,0.2000
STEEL 4340 AISI OQ 1000F 1.0 IN. ROUND,7.8611E-09,2.0477E+05,7.9370E+04,1.6252E+05,0.2900,1.1445E+03,1.2066E+03,14.200,1.1340E-11,0.2000
STEEL 4340 AISI OQ 1000F 2 IN. ROUND,7.8611E-09,2.0477E+05,7.9370E+04,1.6252E+05,0.2900,1.1032E+03,1.1721E+03,16.000,1.1340E-11,0.2000
STEEL 4340 AISI OQ 1000F 4 IN. ROUND,7.8611E-09,2.0477E+05,7.9370E+04,1.6252E+05,0.2900,9.9974E+02,1.1376E+03,15.500,1.1340E-11,0.2000
STEEL 4340 AISI OQ 1100F 0.5 IN. ROUND,7.8611E-09,2.0477E+05,7.9370E+04,1.6252E+05,0.2900,1.1170E+03,1.1445E+03,17.100,1.1340E-11,0.2000
STEEL 4340 AISI OQ 1100F 1.0 IN. ROUND,7.8611E-09,2.0477E+05,7.9370E+04,1.6252E+05,0.2900,1.0963E+03,1.1376E+03,16.500,1.1340E-11,0.2000
STEEL 4340 AISI OQ 1100F 2 IN. ROUND,7.8611E-09,2.0477E+05,7.9370E+04,1.6252E+05,0.2900,9.5837E+02,1.0135E+03,19.000,1.1340E-11,0.2000
STEEL 4340 AISI OQ 1100F 4 IN. ROUND,7.8611E-09,2.0477E+05,7.9370E+04,1.6252E+05,0.2900,7.8600E+02,9.2390E+02,19.700,1.1340E-11,0.2000
STEEL 4340 AISI OQ 1200F 0.5 IN. ROUND,7.8611E-09,2.0477E+05,7.9370E+04,1.6252E+05,0.2900,9.3769E+02,9.9974E+02,20.000,1.1340E-11,0.2000
STEEL 4340 AISI OQ 1200F 1.0 IN. ROUND,7.8611E-09,2.0477E+05,7.9370E+04,1.6252E+05,0.2900,8.8253E+02,9.5837E+02,20.000,1.1340E-11,0.2000
STEEL 4340 AISI OQ 1200F 2 IN. ROUND,7.8611E-09,2.0477E+05,7.9370E+04,1.6252E+05,0.2900,8.3427E+02,9.3079E+02,20.500,1.1340E-11,0.2000
STEEL 4340 AISI OQ 1200F 4 IN. ROUND,7.8611E-09,2.0477E+05,7.9370E+04,1.6252E+05,0.2900,7.3084E+02,8.5495E+02,21.700,1.1340E-11,0.2000
STEEL WROUGHT 4340 1 IN. BAR OQ+800F,7.8334E-09,2.0684E+05,8.0172E+04,1.6416E+05,0.2900,1.3790E+03,1.5306E+03,12.000,1.1340E-11,0.2000
STEEL WROUGHT 4340 1 IN. BAR OQ+400F,7.8334E-09,2.0684E+05,8.0172E+04,1.6416E+05,0.2900,1.6410E+03,1.9512E+03,11.000,1.1340E-11,0.2000
STEEL WROUGHT 4140 1 IN. BAR ANNEALED,7.8334E-09,1.9995E+05,7.7499E+04,1.5869E+05,0.2900,4.2058E+02,6.5500E+02,26.000,1.1160E-11,0.2000
STEEL WROUGHT 4140 1 IN. BAR NORM,7.8334E-09,1.9995E+05,7.7499E+04,1.5869E+05,0.2900,6.5500E+02,1.0204E+03,18.000,1.1160E-11,0.2000
STEEL WROUGHT 4140 1 IN. BAR OQ+1200F,7.8334E-09,2.0684E+05,8.0172E+04,1.6416E+05,0.2900,6.5500E+02,7.5842E+02,18.000,1.1160E-11,0.2000
STEEL WROUGHT 4140 1 IN. BAR OQ+1000F,7.8334E-09,2.0684E+05,8.0172E+04,1.6416E+05,0.2900,9.8595E+02,1.1376E+03,15.000,1.1160E-11,0.2000
STEEL WROUGHT 4140 1 IN. BAR OQ+400F,7.8334E-09,2.0684E+05,8.0172E+04,1.6416E+05,0.2900,1.6410E+03,1.7720E+03,8.000,1.1160E-11,0.2000
GRADE 8 BOLT MATERIAL,7.8334E-09,2.0684E+05,8.0172E+04,1.6416E+05,0.2900,8.9632E+02,1.0342E+03,18.000,1.1340E-11,0.2000
HIGH CARBON SPRING STEEL 1080 ASTM 684,7.8611E-09,2.0477E+05,7.9370E+04,1.6252E+05,0.2900,8.6874E+02,1.2686E+03,12.100,1.1340E-11,0.2000
CARTRIDGE BRASS CU 70 ZN 30 DEAD SOFT,8.5254E-09,1.1032E+05,4.1472E+04,1.0815E+05,0.3300,7.5842E+01,3.0337E+02,68.000,1.9980E-11,0.5000
CARTRIDGE BRASS CU 70 ZN 30 ANNEALED,8.5254E-09,1.1032E+05,4.1472E+04,1.0815E+05,0.3300,1.3100E+02,3.5163E+02,55.000,1.9980E-11,0.5000
CARTRIDGE BRASS CU 70 ZN 30 1/4 HARD,8.5254E-09,1.1032E+05,4.1472E+04,1.0815E+05,0.3300,2.7579E+02,3.7232E+02,43.000,1.9980E-11,0.5000
CARTRIDGE BRASS CU 70 ZN 30 1/2 HARD,8.5254E-09,1.1032E+05,4.1472E+04,1.0815E+05,0.3300,3.5853E+02,4.2748E+02,24.000,1.9980E-11,0.5000
CARTRIDGE BRASS CU 70 ZN 30 FULL HARD,8.5254E-09,1.1032E+05,4.1472E+04,1.0815E+05,0.3300,4.3437E+02,5.2400E+02,8.000,1.9980E-11,0.5000
CARTRIDGE BRASS CU 70 ZN 30 EXTRA HARD,8.5254E-09,1.1032E+05,4.1472E+04,1.0815E+05,0.3300,4.4816E+02,5.9295E+02,5.000,1.9980E-11,0.5000